Workbook
Name Cause: 'H:\Users\charo\OneDrive\Desktop\Pondy1 - Daily record 2021.xlsx'!TableSubMainCause[Sub Main Cause]
Name CustomerFeedback: 'H:\Users\charo\OneDrive\Desktop\Pondy1 - Daily record 2021.xlsx'!TableCustomerFeedback[Customer Feedback]
Name CustomerFeedback: 'H:\Users\charo\OneDrive\Desktop\Pondy1 - Daily record 2021.xlsx'!TableCustomerFeedback[Customer Feedback]
Name CustomerStatus: 'H:\Users\charo\OneDrive\Desktop\Pondy1 - Daily record 2021.xlsx'!TableCustomerStatus[Customer status]
Name CustomerStatus: 'H:\Users\charo\OneDrive\Desktop\Pondy1 - Daily record 2021.xlsx'!TableCustomerStatus[Customer status]
Name FirstPassStatus: 'H:\Users\charo\OneDrive\Desktop\Pondy1 - Daily record 2021.xlsx'!Table1stPassStatus[1stPassStatus]
Name FirstPassStatus: 'H:\Users\charo\OneDrive\Desktop\Pondy1 - Daily record 2021.xlsx'!Table1stPassStatus[1stPassStatus]
Name Gudur: 'H:\Users\charo\OneDrive\Desktop\Pondy1 - Daily record 2021.xlsx'!TableMatGD[Gudur]
Name Gudur: 'H:\Users\charo\OneDrive\Desktop\Pondy1 - Daily record 2021.xlsx'!TableMatGD[Gudur]
Name Hatchery: 'H:\Users\charo\OneDrive\Desktop\Pondy1 - Daily record 2021.xlsx'!TableHatchery[Hatchery]
Name Hatchery: 'H:\Users\charo\OneDrive\Desktop\Pondy1 - Daily record 2021.xlsx'!TableHatchery[Hatchery]
Name MainCause: 'H:\Users\charo\OneDrive\Desktop\Pondy1 - Daily record 2021.xlsx'!TableMainCause[Main Cause]
Name MainCause: 'H:\Users\charo\OneDrive\Desktop\Pondy1 - Daily record 2021.xlsx'!TableMainCause[Main Cause]
Name MarketArea: '[1]Pondy1 - Daily record 2020_Revi'!#REF!
Name MarketArea: 'H:\Users\charo\OneDrive\Desktop\Pondy1 - Daily record 2021.xlsx'!TableMarketArea[MarketArea]
Name MarketArea: 'H:\Users\charo\OneDrive\Desktop\Pondy1 - Daily record 2021.xlsx'!TableMarketArea[MarketArea]
Name Maturation: 'H:\Users\charo\OneDrive\Desktop\Pondy1 - Daily record 2021.xlsx'!TableMat[Maturation]
Name Maturation: 'H:\Users\charo\OneDrive\Desktop\Pondy1 - Daily record 2021.xlsx'!TableMat[Maturation]
Name MType: 'H:\Users\charo\OneDrive\Desktop\Pondy1 - Daily record 2021.xlsx'!TableMType[Management Type]
Name MType: 'H:\Users\charo\OneDrive\Desktop\Pondy1 - Daily record 2021.xlsx'!TableMType[Management Type]
Name Nellore: 'H:\Users\charo\OneDrive\Desktop\Pondy1 - Daily record 2021.xlsx'!TableMatNL[Nellore]
Name Nellore: 'H:\Users\charo\OneDrive\Desktop\Pondy1 - Daily record 2021.xlsx'!TableMatNL[Nellore]
Name NpStage: 'H:\Users\charo\OneDrive\Desktop\Pondy1 - Daily record 2021.xlsx'!TableNPStage[NpStage]
Name NpStage: 'H:\Users\charo\OneDrive\Desktop\Pondy1 - Daily record 2021.xlsx'!TableNPStage[NpStage]
Name Ongole: 'H:\Users\charo\OneDrive\Desktop\Pondy1 - Daily record 2021.xlsx'!TableMatOG[Ongole]
Name Ongole: 'H:\Users\charo\OneDrive\Desktop\Pondy1 - Daily record 2021.xlsx'!TableMatOG[Ongole]
Name PackingType: 'H:\Users\charo\OneDrive\Desktop\Pondy1 - Daily record 2021.xlsx'!TablePackingType[Packing Type]
Name PackingType: 'H:\Users\charo\OneDrive\Desktop\Pondy1 - Daily record 2021.xlsx'!TablePackingType[Packing Type]
Name Parameter: 'H:\Users\charo\OneDrive\Desktop\Pondy1 - Daily record 2021.xlsx'!TableParameter[Parameter]
Name Parameter: 'H:\Users\charo\OneDrive\Desktop\Pondy1 - Daily record 2021.xlsx'!TableParameter[Parameter]
Name Pondy: 'H:\Users\charo\OneDrive\Desktop\Pondy1 - Daily record 2021.xlsx'!TableMatPD[Pondy]
Name Pondy: 'H:\Users\charo\OneDrive\Desktop\Pondy1 - Daily record 2021.xlsx'!TableMatPD[Pondy]
Name Pondy1: 'H:\Users\kampol\DATA 2020\Daily Record 2020\Ongole\Ongole - Daily Record_Revise.xlsx'!TableMatPD[Pondy1]
Name PortDest: '[1]Pondy1 - Daily record 2020_Revi'!#REF!
Name PortDest: 'H:\Users\charo\OneDrive\Desktop\Pondy1 - Daily record 2021.xlsx'!TablePortDest[PortDest]
Name PortDest: 'H:\Users\charo\OneDrive\Desktop\Pondy1 - Daily record 2021.xlsx'!TablePortDest[PortDest]
Name ProductStatus: 'H:\Users\charo\OneDrive\Desktop\Pondy1 - Daily record 2021.xlsx'!TableProductStatus[Product status]
Name ProductStatus: 'H:\Users\charo\OneDrive\Desktop\Pondy1 - Daily record 2021.xlsx'!TableProductStatus[Product status]
Name SellingStatus: 'H:\Users\charo\OneDrive\Desktop\Pondy1 - Daily record 2021.xlsx'!TableSellingStatus[Selling status]
Name SellingStatus: 'H:\Users\charo\OneDrive\Desktop\Pondy1 - Daily record 2021.xlsx'!TableSellingStatus[Selling status]
Name SubMainCause: 'H:\Users\charo\OneDrive\Desktop\Pondy1 - Daily record 2021.xlsx'!TableSubMainCause[Sub Main Cause]
Name SubMainCause: 'H:\Users\charo\OneDrive\Desktop\Pondy1 - Daily record 2021.xlsx'!TableSubMainCause[Sub Main Cause]
Name Territory: 'H:\Users\charo\OneDrive\Desktop\Pondy1 - Daily record 2021.xlsx'!TableTerritory[Territory]
Name Territory: 'H:\Users\charo\OneDrive\Desktop\Pondy1 - Daily record 2021.xlsx'!TableTerritory[Territory]
Name Transportation: '[1]Pondy1 - Daily record 2020_Revi'!#REF!
Name Transportation: 'H:\Users\charo\OneDrive\Desktop\Pondy1 - Daily record 2021.xlsx'!TableTransportation[Transportation]
Name Transportation: 'H:\Users\charo\OneDrive\Desktop\Pondy1 - Daily record 2021.xlsx'!TableTransportation[Transportation]
Name TypeOfProduct: 'H:\Users\charo\OneDrive\Desktop\Pondy1 - Daily record 2021.xlsx'!TableTypeOfProduct[Type of Product]
Name TypeOfProduct: 'H:\Users\charo\OneDrive\Desktop\Pondy1 - Daily record 2021.xlsx'!TableTypeOfProduct[Type of Product]
Name Unit: 'H:\Users\charo\OneDrive\Desktop\Pondy1 - Daily record 2021.xlsx'!TableUnit[Unit]
Name Unit: 'H:\Users\charo\OneDrive\Desktop\Pondy1 - Daily record 2021.xlsx'!TableUnit[Unit]
Name Vijaya1: 'H:\Users\charo\OneDrive\Desktop\Pondy1 - Daily record 2021.xlsx'!TableMatVJ1[Vijaya1]
Name Vijaya1: 'H:\Users\charo\OneDrive\Desktop\Pondy1 - Daily record 2021.xlsx'!TableMatVJ1[Vijaya1]
Name Vijaya2: 'H:\Users\charo\OneDrive\Desktop\Pondy1 - Daily record 2021.xlsx'!TableMatVJ2[Vijaya2]
Name Vijaya2: 'H:\Users\charo\OneDrive\Desktop\Pondy1 - Daily record 2021.xlsx'!TableMatVJ2[Vijaya2]

Sheet Explaination sheet
A1: Type of Product | B1: Product status | C1: Detail of Product
A2: PL4 | B2: Np - PL4 | C2: Nauplius stocking and culture up to PL4 and PL4 Transfer to CP hatchery .
B3: Np - PL4 Seed Bank | C3: Nauplius stocking and culture up to PL4 then sell to Dealer.
C4: ( Dealer will culture till 4-7 days and sell to his customer)
A5: Flight | B5: Np - PL10 Flight | C5: Np stocking to culture to PL10 or sell to customer after pass the flight standard
B6: PL4 - PL10 Flight | C6: PL4 stocking to culture to PL10 or sell to customer after pass the flight standard
A7: PL12 | B7: Np - PL12 | C7: Np stocking and culture to PL12 or sell to customer after pass the PL-QC standard
B8: PL4 - PL12 | C8: PL4 stocking and culture to PL12 or sell to customer after pass the PL-QC standard
A9: SuperPL | B9: Np - SuperPL | C9: Nauplius stocking and culture up to Super PL and sell to customer
B10: PL4 - SuperPL | C10: PL4 stocking and culture up to Super PL and sell to customer

Sheet STD_01122025
A1: Start Date | B1: Parameter | C1: STD PL4 | D1: formular | E1: STD PL12 | F1: formular | G1: STD SuperPL | H1: formular | I1: STD Flight | J1: formular
A2: 44896 | B2: DOC | C2: - | E2: 16 | F2: 23 | G2: - | I2: -
B3: TL | C3: 6 | D3: 5.999 | E3: 7.5 | F3: 7.499 | G3: 11 | H3: 10.999 | I3: 7 | J3: 6.999
B4: %CV | C4: 7 | D4: 7.001 | E4: 10 | F4: 10.001 | G4: 15 | H4: 15.001 | I4: 8 | J4: 8.001
B5: %TL | C5: - | E5: 70 | F5: 69.999 | G5: 99 | H5: 98.999 | I5: -
B6: %ST | C6: 80 | D6: 79.999 | E6: 90 | F6: 89.999 | G6: 90 | H6: 89.999 | I6: 85 | J6: 84.999
B7: GVC | C7: ND | D7: ND | E7: ND | F7: 1 | G7: ND | I7: ND
B8: LB | C8: ND | E8: ND | F8: 1 | G8: ND | I8: ND

Sheet Unit
A1: Tank No. | B1: Volumn
A2: A1-01 | B2: 16 | D2: Vijaya2
A3: A1-02 | B3: 16 | D3: Unit | E3: Tank No. | F3: Water Volume | G3: Tank Volume
A4: A1-03 | B4: 16 | F4: (Ton) | G4: (Ton)
A5: A1-04 | B5: 16 | D5: A | E5: 1 - 10 | F5: 16 | G5: 18 | H5: =(RIGHT(E5,2)-LEFT(E5,2)+1)*F5 -> 160
A6: A1-05 | B6: 16 | E6: 11 - 20 | F6: 8 | G6: 10 | H6: =(RIGHT(E6,2)-LEFT(E6,2)+1)*F6 -> 80
A7: A1-06 | B7: 16 | D7: B | E7: 1 - 8 | F7: 12 | G7: 10 | H7: =(RIGHT(E7,2)-LEFT(E7,2)+1)*F7 -> 96
A8: A1-07 | B8: 16 | D8: C | E8: 1 - 8 | F8: 20 | G8: 20 | H8: =(RIGHT(E8,2)-LEFT(E8,2)+1)*F8 -> 160
A9: A1-08 | B9: 16 | D9: D | E9: 1 - 10 | F9: 20 | G9: 20 | H9: =(RIGHT(E9,2)-LEFT(E9,2)+1)*F9 -> 200
A10: A1-09 | B10: 16 | D10: E | E10: 1 - 12 | F10: 10 | G10: 20 | H10: =(RIGHT(E10,2)-LEFT(E10,2)+1)*F10 -> 120
A11: A1-10 | B11: 16 | D11: Revise : 151218 | H11: =SUM(H5:H10) -> 816
A12: A1-11 | B12: 8
A13: A1-12 | B13: 8
A14: A1-13 | B14: 8
A15: A1-14 | B15: 8
A16: A1-15 | B16: 8
A17: A1-16 | B17: 8
A18: A1-17 | B18: 8
A19: A1-18 | B19: 8
A20: A1-19 | B20: 8
A21: A1-20 | B21: 8
A22: B1-01 | B22: 12
A23: B1-02 | B23: 12
... A59: E1-12 | B59: 10
B60: =SUM(B2:B59) -> 816

Sheet List
A1: Hatchery | B1: Maturation | C1: Brooder Source | D1: Gudur | E1: Nellore | F1: Ongole | G1: Pondy | H1: Vijaya1 | I1: Vijaya2 | J1: Unit | K1: NpStage | L1: Type of Product | M1: Product status | N1: MarketArea | O1: Customer status | P1: Selling status | Q1: Customer Feedback | R1: Packing Type | S1: 1stPassStatus | T1: Parameter | U1: STD PL4 | V1: STD PL12 | W1: STD SuperPL | X1: Management Type | Y1: Main Cause | Z1: Sub Main Cause | AA1: Parameter | AB1: Territory | AC1: Transportation | AD1: PortDest
A2: FB | B2: Gudur | C2: CP-Rocket | D2: GD-MA1 | E2: NL-MA1 | F2: OG-MA1 | G2: PD-MA1 | H2: V1-MA1 | I2: V2-MA1 | J2: A1 | K2: Np2 | L2: PL4 | M2: Np - PL4 | N2: CENTRAL-1 | O2: CP Hatchery | P2: Pass: Sold | Q2: Satisfied | R2: QPASS Tank | S2: Pass | T2: DOC | U2: - | V2: 21 | W2: - | X2: Drain | Y2: Out of order | Z2: Out of order | AA2: EHP | AB2: North | AC2: Flight | AD2: Kolkata
A3: Gujarat2 | B3: Nellore | C3: CP-Kong | D3: GD-MA2 | E3: NL-MB1 | F3: OG-MA2 | G3: PD-MB1 | H3: V1-MB1 | I3: V2-MB1 | J3: B1 | K3: Np4 | L3: PL12 | M3: Np - PL4 Seed Bank | N3: CENTRAL-2 | O3: CP Farm | P3: Claim | Q3: Weak & Die | R3: Mini QPASS Tank | S3: Fail | T3: TL | U3: 6 | V3: 8.5 | W3: 11 | X3: Shift | Y3: Out of Standard | Z3: Not pass QC | AA3: VPA | AB3: Central | AC3: Vehicle | AD3: Surat
A4: Pondy1 | B4: Ongole | C4: SyAqua | D4: GD-MB1 | E4: NL-MC1 | F4: OG-MB1 | G4: PD-MC1 | H4: V1-MC1 | J4: C1 | L4: SuperPL | M4: Np - PL10 Flight | N4: CENTRAL-3 | O4: Customer | P4: Seed Support | Q4: Size Variation | R4: Plastic Bag | T4: %CV | U4: 10 | V4: 11 | W4: 15 | X4: Mix | Y4: Return & weak | Z4: Drain with AHPND | AA4: GVC | AB4: South | AD4: Mumbai
A5: Pondy2 | B5: Pondy1 | C5: Konabay | D5: GD-MB2 | E5: NL-MD1 | F5: OG-MB2 | G5: PD-MD1 | H5: V1-MD1 | J5: D1 | L5: Flight | M5: PL4 - PL10 Flight | N5: CENTRAL-4 | P5: Fail: Sold with Approved letter | Q5: Shortage | T5: %TL | U5: - | V5: 80 | W5: 99 | X5: Separate | Y5: Other damage | Z5: Drain with EHP | AA5: LB | AB5: West
A6: Gudur | B6: Vijaya1 | C6: SIS | D6: GD-MC1 | J6: E1 | M6: Np - PL12 | N6: CENTRAL-5 | P6: Fail: Sold without Approved letter | Q6: Reject | T6: %ST | U6: - | V6: 90 | W6: 90 | Y6: Size Selection | Z6: Drain with GVC | AA6: TL
A7: Nellore | B7: Vijaya2 | J7: G1 | M7: PL4 - PL12 | N7: CENTRAL-6 | T7: GVC | U7: - | V7: 1000 | W7: 1000 | Z7: Drain with Deformity | AA7: %TL
A8: Ongole | M8: Np - SuperPL | N8: CENTRAL-7 | T8: LB | U8: - | V8: ND | W8: ND | Z8: Drain with other virus | AA8: %CV
A9: Vijaya1 | M9: PL4 - SuperPL | N9: CENTRAL-8 | Z9: Size | AA9: Stress test
A10: Vijaya2 | N10: CENTRAL-9 | Z10: Salinity | AA10: DoC Over
A11: AMP | N11: CENTRAL-10 | Z11: Shortage | AA11: Melanize
A12: Gujarat1 | N12: WB-1 | Z12: Claim Np 100% | AA12: Necrosis
A13: Gold River | N13: WB-2 | Z13: Weak at Zoea stage | AA13: Ectoparasite
N14: WB-3 | Z14: Weak at Mysis stage | AA14: Pale Color
N15: WB-4 | Z15: Weak at PL stage | AA15: Deform PL
N16: North WB | Z16: Cause of WQ | AA16: Tubular / Lipid
N17: Assam | Z17: Reduce/Less Density
N18: Bihar | Z18: Cause of Fungi
N19: NER | Z19: Drain with QA
N20: NOD-1 | Z20: Drain with Company Policy
N21: NOD-2 | Z21: Size Selection
N22: SOD-1
N23: SOD-2
N24: Gujarat-N
N25: Gujarat-S
N26: UP
N27: Rajasthan
N28: Haryana
N29: Panjab
N30: MP
N31: South Westhern
N32: SIM-1
N33: SIM-2
... N63: KL

Sheet NP sum
A1: Year | B1: 2025
A2: Month | B2: (All)
L3: 8072235052
A4: Row Labels | B4: Sum of No.Np/PL4 Transfer (Mil)
A5: Konabay | B5: 119.3
A6: SIS | B6: 265.692
A7: SyAqua | B7: 106.7
A8: Grand Total | B8: 491.692
A13: Months | B13: Sep
A15: Row Labels | B15: Sum of Total PL Selling (Mil.) | C15: Sum of Total PL Production (Mil.)
A16: SIS | B16: 7903000 | C16: 11837002 | E16: 92166132 | F16: 1.2221693e+08 | H16: =E16/10^6 -> 92.166132 | I16: =F16/10^6 -> 122.21693
A17: SyAqua | B17: 12880700 | C17: 19486113 | E17: 1.7318144e+08 | F17: 2.4043654e+08 | H17: =E17/10^6 -> 173.18144 | I17: =F17/10^6 -> 240.43654
A18: Grand Total | B18: 20783700 | C18: 31323114 | E18: 1300000 | F18: 1830600 | H18: =E18/10^6 -> 1.3 | I18: =F18/10^6 -> 1.8306
E19: 2.6664757e+08 | F19: 3.6448407e+08 | H19: =E19/10^6 -> 266.64757 | I19: =F19/10^6 -> 364.48407
B24: =GETPIVOTDATA("Sum of Total PL Selling (Mil.)",$A$15)/10^6 -> 20.7837 | C24: =GETPIVOTDATA("Sum of Total PL Production (Mil.)",$A$15)/10^6 -> 31.323114
A29: Hatchery | B29: Vijaya2
A31: Row Labels | B31: Sum of Field1 | C31: Sum of Field2
A32: Feb | B32: 50.715081 | C32: 65.922032
A33: Mar | B33: 79.607832 | C33: 105.09407
A34: Apr | B34: 31.098068 | C34: 43.80546
A35: May | B35: 44.565872 | C35: 64.670877
A36: Jul | B36: 73.0106 | C36: 94.115052
A37: Aug | B37: 45.515725 | C37: 61.279579
A38: Sep | B38: 20.7837 | C38: 31.323114
A39: Grand Total | B39: 345.29688 | C39: 466.21019

Sheet Np Quality
A1: MAT-Date | B1: Date | C1: Maturation | D1: MAT Unit | E1: Brooder Source | F1: Np Stage | G1: %FER | H1: %HAT | I1: %Deformity | J1: Size(µm) | K1: Fungus (24 hrs) | L1: Fungus (48 hrs) | M1: %CV <5.0 | N1: PCR STD | O1: Bacteria STD | P1: Actual Np (Mill.) | Q1: Np Transfer (mill.) | R1: Np drained (Mill.) (Good quality) | S1: Np drained (Mill.) (Non quality) | T1: Pondy 1 | U1: FB | V1: Vijaya 1 | W1: Vijaya 2 | X1: Customer | AA1: PCR STD | AB1: Bacteria STD
A2: =D2&"-"&B2 -> PD-MA1-45683 | B2: 45683 | C2: Pondy1 | D2: PD-MA1 | E2: Konabay | F2: NP3 | G2: - | H2: - | I2: 0.01 | J2: 385 | K2: ND | L2: ND | M2: 0.0172 | N2: Pass | O2: Pass | AA2: Pass | AB2: Pass
A3: =D3&"-"&B3 -> PD-MA1-45684 | B3: 45684 | C3: Pondy1 | D3: PD-MA1 | E3: Konabay | F3: NP3 | G3: - | H3: - | I3: 0.02 | J3: 387 | K3: ND | L3: ND | M3: 0.0172 | N3: Pass | O3: Pass | AA3: Fail | AB3: Fail
A4: =D4&"-"&B4 -> PD-MC1-45684 | B4: 45684 | C4: Pondy1 | D4: PD-MC1 | E4: Konabay | F4: NP3 | G4: - | H4: - | I4: 0.02 | J4: 390 | K4: ND | L4: ND | M4: 0.0164 | N4: Pass | O4: Pass
A5: =D5&"-"&B5 -> V1-MD1-45684 | B5: 45684 | C5: Vijaya1 | D5: V1-MD1 | E5: Konabay | F5: Np4 | G5: 0.8 | H5: 0.8 | I5: 0.01 | J5: 480 | K5: ND | L5: ND | M5: 0.0169 | N5: Pass | O5: Pass
A6: =D6&"-"&B6 -> V1-MD1-45685 | B6: 45685 | C6: Vijaya1 | D6: V1-MD1 | E6: Konabay | F6: Np4 | G6: 0.9 | H6: 0.9 | I6: 0 | J6: 487 | K6: ND | L6: ND | M6: 0.0175 | N6: Pass | O6: Pass
A7: =D7&"-"&B7 -> V1-MD1-45686 | B7: 45686 | C7: Vijaya1 | D7: V1-MD1 | E7: Konabay | F7: Np4 | G7: 0.9 | H7: 0.9 | I7: 0.01 | J7: 490 | K7: ND | L7: ND | M7: 0.0182 | N7: Pass | O7: Pass
A8: =D8&"-"&B8 -> PD-MA1-45687 | B8: 45687 | C8: Pondy1 | D8: PD-MA1 | E8: Konabay | F8: NP3 | G8: - | H8: - | I8: 0.02 | J8: 388 | K8: ND | L8: ND | M8: 0.0173 | N8: Pass | O8: Pass
A9: =D9&"-"&B9 -> PD-MC1-45687 | B9: 45687 | C9: Pondy1 | D9: PD-MC1 | E9: Konabay | F9: NP3 | G9: - | H9: - | I9: 0.01 | J9: 390 | K9: ND | L9: ND | M9: 0.0188 | N9: Pass | O9: Pass
A10: =D10&"-"&B10 -> V1-MD1-45687 | B10: 45687 | C10: Vijaya1 | D10: V1-MD1 | E10: Konabay | F10: Np4 | G10: 0.8 | H10: 0.8 | I10: 0.01 | J10: 480 | K10: ND | L10: ND | M10: 0.0202 | N10: Pass | O10: Pass
A11: =D11&"-"&B11 -> V1-MD1-45688 | B11: 45688 | C11: Vijaya1 | D11: V1-MD1 | E11: Konabay | F11: Np4 | G11: 0.9 | H11: 0.9 | I11: 0 | J11: 490 | K11: ND | L11: ND | M11: 0.0192 | N11: Pass | O11: Pass
A12: =D12&"-"&B12 -> V1-MB1-45694 | B12: 45694 | C12: Vijaya1 | D12: V1-MB1 | E12: SIS | F12: Np4 | G12: 0.9 | H12: 0.9 | I12: 0 | J12: 486 | K12: ND | L12: ND | M12: 0.0184 | N12: Pass | O12: Pass
A13: =D13&"-"&B13 -> V1-MD1-45694 | B13: 45694 | C13: Vijaya1 | D13: V1-MD1 | E13: Konabay | F13: Np4 | G13: 0.9 | H13: 0.9 | I13: 0 | J13: 480 | K13: ND | L13: ND | M13: 0.019 | N13: Pass | O13: Pass
A14: =D14&"-"&B14 -> PD-MA1-45695 | B14: 45695 | C14: Pondy1 | D14: PD-MA1 | E14: Konabay | F14: NP3 | G14: - | H14: - | I14: 0.01 | J14: 395 | K14: ND | L14: ND | M14: 0.0175 | N14: Pass | O14: Pass
A15: =D15&"-"&B15 -> V1-MB1-45695 | B15: 45695 | C15: Vijaya1 | D15: V1-MB1 | E15: SIS | F15: Np4 | G15: 0.9 | H15: 0.9 | I15: 0 | J15: 490 | K15: ND | L15: ND | M15: 0.0186 | N15: Pass | O15: Pass
A16: =D16&"-"&B16 -> V1-MD1-45695 | B16: 45695 | C16: Vijaya1 | D16: V1-MD1 | E16: Konabay | F16: Np4 | G16: 0.9 | H16: 0.9 | I16: 0 | J16: 483 | K16: ND | L16: ND | M16: 0.0193 | N16: Pass | O16: Pass
B17: 45696 | C17: Pondy1 | D17: PD-MA1 | E17: Konabay | F17: NP3 | G17: - | H17: - | I17: 0.02 | J17: 386 | K17: ND | L17: ND | M17: 0.016 | N17: Pass | O17: Pass
A18: =D18&"-"&B18 -> V1-MB1-45696 | B18: 45696 | C18: Vijaya1 | D18: V1-MB1 | E18: SIS | F18: Np4 | G18: 0.9 | H18: 0.9 | I18: 0 | J18: 490 | K18: ND | L18: ND | M18: 0.0172 | N18: Pass | O18: Pass
A19: =D19&"-"&B19 -> V1-MD1-45696 | B19: 45696 | C19: Vijaya1 | D19: V1-MD1 | E19: Konabay | F19: Np4 | G19: 0.9 | H19: 0.9 | I19: 0 | J19: 486 | K19: ND | L19: ND | M19: 0.018 | N19: Pass | O19: Pass
A20: =D20&"-"&B20 -> V1-MB1-45697 | B20: 45697 | C20: Vijaya1 | D20: V1-MB1 | E20: SIS | F20: Np4 | G20: 0.9 | H20: 0.9 | I20: 0 | J20: 488 | K20: ND | L20: ND | M20: 0.0191 | N20: Pass | O20: Pass
A21: =D21&"-"&B21 -> V1-MD1-45697 | B21: 45697 | C21: Vijaya1 | D21: V1-MD1 | E21: Konabay | F21: Np4 | G21: 0.9 | H21: 0.9 | I21: 0.01 | J21: 478 | K21: ND | L21: ND | M21: 0.0188 | N21: Pass | O21: Pass
A22: =D22&"-"&B22 -> PD-MA1-45699 | B22: 45699 | C22: Pondy1 | D22: PD-MA1 | E22: Konabay | F22: Np4 | G22: - | H22: - | I22: 0.01 | J22: 474 | K22: ND | L22: ND | M22: 0.0169 | N22: Pass | O22: Pass
A23: =D23&"-"&B23 -> V1-MB1-45699 | B23: 45699 | C23: Vijaya1 | D23: V1-MB1 | E23: SIS | F23: Np4 | G23: 0.9 | H23: 0.9 | I23: 0 | J23: 490 | K23: ND | L23: ND | M23: 0.0188 | N23: Pass | O23: Pass
A24: =D24&"-"&B24 -> PD-MA1-45700 | B24: 45700 | C24: Pondy1 | D24: PD-MA1 | E24: Konabay | F24: Np4 | G24: - | H24: - | I24: 0 | J24: 476 | K24: ND | L24: ND | M24: 0.0159 | N24: Pass | O24: Pass
A25: =D25&"-"&B25 -> V1-MB1-45700 | B25: 45700 | C25: Vijaya1 | D25: V1-MB1 | E25: SIS | F25: Np4 | G25: 0.9 | H25: 0.9 | I25: 0.01 | J25: 486 | K25: ND | L25: ND | M25: 0.0182 | N25: Pass | O25: Pass
A26: =D26&"-"&B26 -> V1-MD1-45700 | B26: 45700 | C26: Vijaya1 | D26: V1-MD1 | E26: Konabay | F26: Np4 | G26: 0.9 | H26: 0.9 | I26: 0 | J26: 480 | K26: ND | L26: ND | M26: 0.0177 | N26: Pass | O26: Pass
A27: =D27&"-"&B27 -> V1-MB1-45701 | B27: 45701 | C27: Vijaya1 | D27: V1-MB1 | E27: SIS | F27: Np4 | G27: 0.9 | H27: 0.9 | I27: 0 | J27: 490 | K27: ND | L27: ND | M27: 0.0198 | N27: Pass | O27: Pass
A28: =D28&"-"&B28 -> V1-MD1-45701 | B28: 45701 | C28: Vijaya1 | D28: V1-MD1 | E28: Konabay | F28: Np4 | G28: 0.9 | H28: 0.9 | I28: 0 | J28: 486 | K28: ND | L28: ND | M28: 0.0181 | N28: Pass | O28: Pass
A29: =D29&"-"&B29 -> V1-MB1-45705 | B29: 45705 | C29: Vijaya1 | D29: V1-MB1 | E29: SIS | F29: Np4 | G29: 0.9 | H29: 0.9 | I29: 0 | J29: 492 | K29: ND | L29: ND | M29: 0.0179 | N29: Pass | O29: Pass
A30: =D30&"-"&B30 -> V1-MD1-45705 | B30: 45705 | C30: Vijaya1 | D30: V1-MD1 | E30: Konabay | F30: Np4 | G30: 0.9 | H30: 0.9 | I30: 0 | J30: 484 | K30: ND | L30: ND | M30: 0.0165 | N30: Pass | O30: Pass
A31: =D31&"-"&B31 -> V1-MB1-45706 | B31: 45706 | C31: Vijaya1 | D31: V1-MB1 | E31: SIS | F31: Np4 | G31: 0.9 | H31: 0.9 | I31: 0 | J31: 492 | K31: ND | L31: ND | M31: 0.0173 | N31: Pass | O31: Pass
A32: =D32&"-"&B32 -> V1-MD1-45706 | B32: 45706 | C32: Vijaya1 | D32: V1-MD1 | E32: Konabay | F32: Np4 | G32: 0.9 | H32: 0.9 | I32: 0 | J32: 486 | K32: ND | L32: ND | M32: 0.0167 | N32: Pass | O32: Pass
A33: =D33&"-"&B33 -> V1-MD1-45707 | B33: 45707 | C33: Vijaya1 | D33: V1-MD1 | E33: Konabay | F33: Np4 | G33: 0.9 | H33: 0.9 | I33: 0 | J33: 482 | K33: ND | L33: ND | M33: 0.0171 | N33: Pass | O33: Pass
A34: =D34&"-"&B34 -> V1-MD1-45708 | B34: 45708 | C34: Vijaya1 | D34: V1-MD1 | E34: Konabay | F34: Np4 | G34: 0.9 | H34: 0.9 | I34: 0 | J34: 488 | K34: ND | L34: ND | M34: 0.0175 | N34: Pass | O34: Pass
A35: =D35&"-"&B35 -> V1-MD1-45708 | B35: 45708 | C35: Vijaya1 | D35: V1-MD1 | E35: Konabay | F35: Np4 | G35: 0.9 | H35: 0.9 | I35: 0 | J35: 488 | K35: ND | L35: ND | M35: 0.0175 | N35: Pass | O35: Pass
A36: =D36&"-"&B36 -> PD-MA1-45709 | B36: 45709 | C36: Pondy1 | D36: PD-MA1 | E36: Konabay | F36: Np4 | G36: - | H36: - | I36: 0.02 | J36: 472 | K36: ND | L36: ND | M36: 0.0161 | N36: Pass | O36: Pass
A37: =D37&"-"&B37 -> V1-MB1-45710 | B37: 45710 | C37: Vijaya1 | D37: V1-MB1 | E37: SIS | F37: Np4 | G37: 0.9 | H37: 0.9 | I37: 0 | J37: 498 | K37: ND | L37: ND | M37: 0.0189 | N37: Pass | O37: Pass
A38: =D38&"-"&B38 -> V1-MD1-45710 | B38: 45710 | C38: Vijaya1 | D38: V1-MD1 | E38: Konabay | F38: Np4 | G38: 0.9 | H38: 0.9 | I38: 0 | J38: 488 | K38: ND | L38: ND | M38: 0.0163 | N38: Pass | O38: Pass
A39: =D39&"-"&B39 -> V1-MB1-45711 | B39: 45711 | C39: Vijaya1 | D39: V1-MB1 | E39: SIS | F39: Np4 | G39: 0.9 | H39: 0.9 | I39: 0 | J39: 495 | K39: ND | L39: ND | M39: 0.0191 | N39: Pass | O39: Pass
A40: =D40&"-"&B40 -> V1-MD1-45711 | B40: 45711 | C40: Vijaya1 | D40: V1-MD1 | E40: Konabay | F40: Np4 | G40: 0.9 | H40: 0.9 | I40: 0 | J40: 486 | K40: ND | L40: ND | M40: 0.0172 | N40: Pass | O40: Pass
...

Sheet Np PL4 Stock
A1: Tank #Crop | B1: Count Tank #Crop | C1: Hatchery | D1: Management Date | E1: Np / PL4 Stocking Date | F1: DoC at Stocking | G1: Crop | H1: Unit | I1: Tank No. | J1: Np Stage | K1: Maturation | L1: MAT Unit | M1: Brooder Source | N1: No.Np/PL4 Transfer (Mil) | O1: %FER | P1: %HAT | Q1: %Deformity | R1: Size(µm) | S1: Remark | T1: Np Code | U1: B Source | V1: Actual Np (mill.) | W1: Closed Date | X1: Month | Y1: Year
A2: =IF(ISBLANK(H2),"",H2&"-"&IF(OR(LEN(I2)=1,LEN(I2)=4),"0"&I2,I2)&"-"&IF(LEN(G2)=1,"0"&G2,G2)) -> C1-01-01 | B2: =IF(AND(A2<>A1,A2<>""),COUNTIF(A:A,A2),"") -> 1 | C2: Vijaya2 | D2: 45683 | E2: =IF(ISBLANK(D2),"",D2-F2) -> 45683 | F2: 0 | G2: 1 | H2: C1 | I2: 1 | J2: Np4 | K2: Pondy1 | L2: PD-MA1 | M2: Konabay | N2: 1 | O2: =IF(ISBLANK(L2),"",IF(OR(ISBLANK(VLOOKUP(L2&"-"&E2,'Np Quality'!A:M,6,FALSE)),ISERROR(VLOOKUP(L2&"-"&E2,'Np Quality'!A:M,6,FALSE))),"-",VLOOKUP(L2&"-"&E2,'Np Quality'!A:M,6,FALSE))) -> NP3 | P2: =IF(ISBLANK(L2),"",IF(OR(ISBLANK(VLOOKUP(L2&"-"&E2,'Np Quality'!A:M,7,FALSE)),ISERROR(VLOOKUP(L2&"-"&E2,'Np Quality'!A:M,7,FALSE))),"-",VLOOKUP(L2&"-"&E2,'Np Quality'!A:M,7,FALSE))) -> - | Q2: =IF(ISBLANK(L2),"",IF(OR(ISBLANK(VLOOKUP(L2&"-"&E2,'Np Quality'!A:M,8,FALSE)),ISERROR(VLOOKUP(L2&"-"&E2,'Np Quality'!A:M,8,FALSE))),"-",VLOOKUP(L2&"-"&E2,'Np Quality'!A:M,8,FALSE))) -> - | R2: =IF(ISBLANK(L2),"",IF(OR(ISBLANK(VLOOKUP(L2&"-"&E2,'Np Quality'!A:M,9,FALSE)),ISERROR(VLOOKUP(L2&"-"&E2,'Np Quality'!A:M,9,FALSE))),"-",VLOOKUP(L2&"-"&E2,'Np Quality'!A:M,9,FALSE))) -> 0.01 | T2: =IF(ISNUMBER(B2),CHOOSE(B2,L2,L2&","&L3,L2&","&L3&","&L4,L2&","&L3&","&L4&","&L5),"") -> PD-MA1 | U2: =IF(ISNUMBER(B2),CHOOSE(B2,M2,M2&","&M3,M2&","&M3&","&M4,M2&","&M3&","&M4&","&M5),"") -> Konabay | W2: 45697 | X2: =MONTH(W2) -> 2 | Y2: =YEAR(W2) -> 2025
A3: =IF(ISBLANK(H3),"",H3&"-"&IF(OR(LEN(I3)=1,LEN(I3)=4),"0"&I3,I3)&"-"&IF(LEN(G3)=1,"0"&G3,G3)) -> C1-02-01 | B3: =IF(AND(A3<>A2,A3<>""),COUNTIF(A:A,A3),"") -> 1 | C3: Vijaya2 | D3: 45683 | E3: =IF(ISBLANK(D3),"",D3-F3) -> 45683 | F3: 0 | G3: 1 | H3: C1 | I3: 2 | J3: Np4 | K3: Pondy1 | L3: PD-MA1 | M3: Konabay | N3: 1 | O3: =IF(ISBLANK(L3),"",IF(OR(ISBLANK(VLOOKUP(L3&"-"&E3,'Np Quality'!A:M,6,FALSE)),ISERROR(VLOOKUP(L3&"-"&E3,'Np Quality'!A:M,6,FALSE))),"-",VLOOKUP(L3&"-"&E3,'Np Quality'!A:M,6,FALSE))) -> NP3 | P3: =IF(ISBLANK(L3),"",IF(OR(ISBLANK(VLOOKUP(L3&"-"&E3,'Np Quality'!A:M,7,FALSE)),ISERROR(VLOOKUP(L3&"-"&E3,'Np Quality'!A:M,7,FALSE))),"-",VLOOKUP(L3&"-"&E3,'Np Quality'!A:M,7,FALSE))) -> - | Q3: =IF(ISBLANK(L3),"",IF(OR(ISBLANK(VLOOKUP(L3&"-"&E3,'Np Quality'!A:M,8,FALSE)),ISERROR(VLOOKUP(L3&"-"&E3,'Np Quality'!A:M,8,FALSE))),"-",VLOOKUP(L3&"-"&E3,'Np Quality'!A:M,8,FALSE))) -> - | R3: =IF(ISBLANK(L3),"",IF(OR(ISBLANK(VLOOKUP(L3&"-"&E3,'Np Quality'!A:M,9,FALSE)),ISERROR(VLOOKUP(L3&"-"&E3,'Np Quality'!A:M,9,FALSE))),"-",VLOOKUP(L3&"-"&E3,'Np Quality'!A:M,9,FALSE))) -> 0.01 | T3: =IF(ISNUMBER(B3),CHOOSE(B3,L3,L3&","&L4,L3&","&L4&","&L5,L3&","&L4&","&L5&","&L6),"") -> PD-MA1 | U3: =IF(ISNUMBER(B3),CHOOSE(B3,M3,M3&","&M4,M3&","&M4&","&M5,M3&","&M4&","&M5&","&M6),"") -> Konabay | W3: 45697 | X3: =MONTH(W3) -> 2 | Y3: =YEAR(W3) -> 2025
A4: =IF(ISBLANK(H4),"",H4&"-"&IF(OR(LEN(I4)=1,LEN(I4)=4),"0"&I4,I4)&"-"&IF(LEN(G4)=1,"0"&G4,G4)) -> C1-03-01 | B4: =IF(AND(A4<>A3,A4<>""),COUNTIF(A:A,A4),"") -> 1 | C4: Vijaya2 | D4: 45683 | E4: =IF(ISBLANK(D4),"",D4-F4) -> 45683 | F4: 0 | G4: 1 | H4: C1 | I4: 3 | J4: Np4 | K4: Pondy1 | L4: PD-MA1 | M4: Konabay | N4: 1 | O4: =IF(ISBLANK(L4),"",IF(OR(ISBLANK(VLOOKUP(L4&"-"&E4,'Np Quality'!A:M,6,FALSE)),ISERROR(VLOOKUP(L4&"-"&E4,'Np Quality'!A:M,6,FALSE))),"-",VLOOKUP(L4&"-"&E4,'Np Quality'!A:M,6,FALSE))) -> NP3 | P4: =IF(ISBLANK(L4),"",IF(OR(ISBLANK(VLOOKUP(L4&"-"&E4,'Np Quality'!A:M,7,FALSE)),ISERROR(VLOOKUP(L4&"-"&E4,'Np Quality'!A:M,7,FALSE))),"-",VLOOKUP(L4&"-"&E4,'Np Quality'!A:M,7,FALSE))) -> - | Q4: =IF(ISBLANK(L4),"",IF(OR(ISBLANK(VLOOKUP(L4&"-"&E4,'Np Quality'!A:M,8,FALSE)),ISERROR(VLOOKUP(L4&"-"&E4,'Np Quality'!A:M,8,FALSE))),"-",VLOOKUP(L4&"-"&E4,'Np Quality'!A:M,8,FALSE))) -> - | R4: =IF(ISBLANK(L4),"",IF(OR(ISBLANK(VLOOKUP(L4&"-"&E4,'Np Quality'!A:M,9,FALSE)),ISERROR(VLOOKUP(L4&"-"&E4,'Np Quality'!A:M,9,FALSE))),"-",VLOOKUP(L4&"-"&E4,'Np Quality'!A:M,9,FALSE))) -> 0.01 | T4: =IF(ISNUMBER(B4),CHOOSE(B4,L4,L4&","&L5,L4&","&L5&","&L6,L4&","&L5&","&L6&","&L7),"") -> PD-MA1 | U4: =IF(ISNUMBER(B4),CHOOSE(B4,M4,M4&","&M5,M4&","&M5&","&M6,M4&","&M5&","&M6&","&#REF!),"") -> Konabay | W4: 45697 | X4: =MONTH(W4) -> 2 | Y4: =YEAR(W4) -> 2025
A5: =IF(ISBLANK(H5),"",H5&"-"&IF(OR(LEN(I5)=1,LEN(I5)=4),"0"&I5,I5)&"-"&IF(LEN(G5)=1,"0"&G5,G5)) -> C1-04-01 | B5: =IF(AND(A5<>A4,A5<>""),COUNTIF(A:A,A5),"") -> 1 | C5: Vijaya2 | D5: 45683 | E5: =IF(ISBLANK(D5),"",D5-F5) -> 45683 | F5: 0 | G5: 1 | H5: C1 | I5: 4 | J5: Np4 | K5: Pondy1 | L5: PD-MA1 | M5: Konabay | N5: 1 | O5: =IF(ISBLANK(L6),"",IF(OR(ISBLANK(VLOOKUP(L6&"-"&E6,'Np Quality'!A:M,6,FALSE)),ISERROR(VLOOKUP(L6&"-"&E6,'Np Quality'!A:M,6,FALSE))),"-",VLOOKUP(L6&"-"&E6,'Np Quality'!A:M,6,FALSE))) -> NP3 | P5: =IF(ISBLANK(L5),"",IF(OR(ISBLANK(VLOOKUP(L5&"-"&E5,'Np Quality'!A:M,7,FALSE)),ISERROR(VLOOKUP(L5&"-"&E5,'Np Quality'!A:M,7,FALSE))),"-",VLOOKUP(L5&"-"&E5,'Np Quality'!A:M,7,FALSE))) -> - | Q5: =IF(ISBLANK(L5),"",IF(OR(ISBLANK(VLOOKUP(L5&"-"&E5,'Np Quality'!A:M,8,FALSE)),ISERROR(VLOOKUP(L5&"-"&E5,'Np Quality'!A:M,8,FALSE))),"-",VLOOKUP(L5&"-"&E5,'Np Quality'!A:M,8,FALSE))) -> - | R5: =IF(ISBLANK(L5),"",IF(OR(ISBLANK(VLOOKUP(L5&"-"&E5,'Np Quality'!A:M,9,FALSE)),ISERROR(VLOOKUP(L5&"-"&E5,'Np Quality'!A:M,9,FALSE))),"-",VLOOKUP(L5&"-"&E5,'Np Quality'!A:M,9,FALSE))) -> 0.01 | T5: =IF(ISNUMBER(B5),CHOOSE(B5,L5,L5&","&L6,L5&","&L6&","&L7,L5&","&L6&","&L7&","&L8),"") -> PD-MA1 | U5: =IF(ISNUMBER(B5),CHOOSE(B5,M5,M5&","&M6,M5&","&M6&","&#REF!,M5&","&M6&","&#REF!&","&M7),"") -> Konabay | W5: 45696 | X5: =MONTH(W5) -> 2 | Y5: =YEAR(W5) -> 2025
A6: =IF(ISBLANK(H6),"",H6&"-"&IF(OR(LEN(I6)=1,LEN(I6)=4),"0"&I6,I6)&"-"&IF(LEN(G6)=1,"0"&G6,G6)) -> C1-05-01 | B6: =IF(AND(A6<>A5,A6<>""),COUNTIF(A:A,A6),"") -> 1 | C6: Vijaya2 | D6: 45684 | E6: =IF(ISBLANK(D6),"",D6-F6) -> 45684 | F6: 0 | G6: 1 | H6: C1 | I6: 5 | J6: Np4 | K6: Pondy1 | L6: PD-MA1 | M6: Konabay | N6: 1 | O6: =IF(ISBLANK(L6),"",IF(OR(ISBLANK(VLOOKUP(L6&"-"&E6,'Np Quality'!A:M,6,FALSE)),ISERROR(VLOOKUP(L6&"-"&E6,'Np Quality'!A:M,6,FALSE))),"-",VLOOKUP(L6&"-"&E6,'Np Quality'!A:M,6,FALSE))) -> NP3 | P6: =IF(ISBLANK(L7),"",IF(OR(ISBLANK(VLOOKUP(L7&"-"&E7,'Np Quality'!A:M,7,FALSE)),ISERROR(VLOOKUP(L7&"-"&E7,'Np Quality'!A:M,7,FALSE))),"-",VLOOKUP(L7&"-"&E7,'Np Quality'!A:M,7,FALSE))) -> - | Q6: =IF(ISBLANK(L6),"",IF(OR(ISBLANK(VLOOKUP(L6&"-"&E6,'Np Quality'!A:M,8,FALSE)),ISERROR(VLOOKUP(L6&"-"&E6,'Np Quality'!A:M,8,FALSE))),"-",VLOOKUP(L6&"-"&E6,'Np Quality'!A:M,8,FALSE))) -> - | R6: =IF(ISBLANK(L6),"",IF(OR(ISBLANK(VLOOKUP(L6&"-"&E6,'Np Quality'!A:M,9,FALSE)),ISERROR(VLOOKUP(L6&"-"&E6,'Np Quality'!A:M,9,FALSE))),"-",VLOOKUP(L6&"-"&E6,'Np Quality'!A:M,9,FALSE))) -> 0.02 | T6: =IF(ISNUMBER(B6),CHOOSE(B6,L6,L6&","&L7,L6&","&L7&","&L8,L6&","&L7&","&L8&","&L9),"") -> PD-MA1 | U6: =IF(ISNUMBER(B6),CHOOSE(B6,M5,M5&","&M7,M5&","&M7&","&M8,M5&","&M7&","&M8&","&M9),"") -> Konabay | W6: 45697 | X6: =MONTH(W6) -> 2 | Y6: =YEAR(W6) -> 2025
A7: =IF(ISBLANK(H7),"",H7&"-"&IF(OR(LEN(I7)=1,LEN(I7)=4),"0"&I7,I7)&"-"&IF(LEN(G7)=1,"0"&G7,G7)) -> C1-06-01 | B7: =IF(AND(A7<>A6,A7<>""),COUNTIF(A:A,A7),"") -> 1 | C7: Vijaya2 | D7: 45684 | E7: =IF(ISBLANK(D7),"",D7-F7) -> 45684 | F7: 0 | G7: 1 | H7: C1 | I7: 6 | J7: Np4 | K7: Pondy1 | L7: PD-MA1 | M7: Konabay | N7: 1 | O7: =IF(ISBLANK(L7),"",IF(OR(ISBLANK(VLOOKUP(L7&"-"&E7,'Np Quality'!A:M,6,FALSE)),ISERROR(VLOOKUP(L7&"-"&E7,'Np Quality'!A:M,6,FALSE))),"-",VLOOKUP(L7&"-"&E7,'Np Quality'!A:M,6,FALSE))) -> NP3 | P7: =IF(ISBLANK(L7),"",IF(OR(ISBLANK(VLOOKUP(L7&"-"&E7,'Np Quality'!A:M,7,FALSE)),ISERROR(VLOOKUP(L7&"-"&E7,'Np Quality'!A:M,7,FALSE))),"-",VLOOKUP(L7&"-"&E7,'Np Quality'!A:M,7,FALSE))) -> - | Q7: =IF(ISBLANK(L8),"",IF(OR(ISBLANK(VLOOKUP(L8&"-"&E8,'Np Quality'!A:M,8,FALSE)),ISERROR(VLOOKUP(L8&"-"&E8,'Np Quality'!A:M,8,FALSE))),"-",VLOOKUP(L8&"-"&E8,'Np Quality'!A:M,8,FALSE))) -> - | R7: =IF(ISBLANK(L7),"",IF(OR(ISBLANK(VLOOKUP(L7&"-"&E7,'Np Quality'!A:M,9,FALSE)),ISERROR(VLOOKUP(L7&"-"&E7,'Np Quality'!A:M,9,FALSE))),"-",VLOOKUP(L7&"-"&E7,'Np Quality'!A:M,9,FALSE))) -> 0.02 | T7: =IF(ISNUMBER(B7),CHOOSE(B7,L7,L7&","&L8,L7&","&L8&","&L9,L7&","&L8&","&L9&","&L10),"") -> PD-MA1 | U7: =IF(ISNUMBER(B7),CHOOSE(B7,M6,M6&","&M8,M6&","&M8&","&M9,M6&","&M8&","&M9&","&M10),"") -> Konabay | W7: 45695 | X7: =MONTH(W7) -> 2 | Y7: =YEAR(W7) -> 2025
A8: =IF(ISBLANK(H8),"",H8&"-"&IF(OR(LEN(I8)=1,LEN(I8)=4),"0"&I8,I8)&"-"&IF(LEN(G8)=1,"0"&G8,G8)) -> C1-07-01 | B8: =IF(AND(A8<>A7,A8<>""),COUNTIF(A:A,A8),"") -> 1 | C8: Vijaya2 | D8: 45684 | E8: =IF(ISBLANK(D8),"",D8-F8) -> 45684 | F8: 0 | G8: 1 | H8: C1 | I8: 7 | J8: Np4 | K8: Pondy1 | L8: PD-MA1 | M8: Konabay | N8: 1 | O8: =IF(ISBLANK(L8),"",IF(OR(ISBLANK(VLOOKUP(L8&"-"&E8,'Np Quality'!A:M,6,FALSE)),ISERROR(VLOOKUP(L8&"-"&E8,'Np Quality'!A:M,6,FALSE))),"-",VLOOKUP(L8&"-"&E8,'Np Quality'!A:M,6,FALSE))) -> NP3 | P8: =IF(ISBLANK(L8),"",IF(OR(ISBLANK(VLOOKUP(L8&"-"&E8,'Np Quality'!A:M,7,FALSE)),ISERROR(VLOOKUP(L8&"-"&E8,'Np Quality'!A:M,7,FALSE))),"-",VLOOKUP(L8&"-"&E8,'Np Quality'!A:M,7,FALSE))) -> - | Q8: =IF(ISBLANK(L8),"",IF(OR(ISBLANK(VLOOKUP(L8&"-"&E8,'Np Quality'!A:M,8,FALSE)),ISERROR(VLOOKUP(L8&"-"&E8,'Np Quality'!A:M,8,FALSE))),"-",VLOOKUP(L8&"-"&E8,'Np Quality'!A:M,8,FALSE))) -> - | R8: =IF(ISBLANK(L9),"",IF(OR(ISBLANK(VLOOKUP(L9&"-"&E9,'Np Quality'!A:M,9,FALSE)),ISERROR(VLOOKUP(L9&"-"&E9,'Np Quality'!A:M,9,FALSE))),"-",VLOOKUP(L9&"-"&E9,'Np Quality'!A:M,9,FALSE))) -> 0.02 | T8: =IF(ISNUMBER(B8),CHOOSE(B8,L8,L8&","&L9,L8&","&L9&","&L10,L8&","&L9&","&L10&","&L11),"") -> PD-MA1 | U8: =IF(ISNUMBER(B8),CHOOSE(B8,M7,M7&","&M9,M7&","&M9&","&M10,M7&","&M9&","&M10&","&M11),"") -> Konabay | W8: 45695 | X8: =MONTH(W8) -> 2 | Y8: =YEAR(W8) -> 2025
A9: =IF(ISBLANK(H9),"",H9&"-"&IF(OR(LEN(I9)=1,LEN(I9)=4),"0"&I9,I9)&"-"&IF(LEN(G9)=1,"0"&G9,G9)) -> C1-08-01 | B9: =IF(AND(A9<>A8,A9<>""),COUNTIF(A:A,A9),"") -> 1 | C9: Vijaya2 | D9: 45684 | E9: =IF(ISBLANK(D9),"",D9-F9) -> 45684 | F9: 0 | G9: 1 | H9: C1 | I9: 8 | J9: Np4 | K9: Pondy1 | L9: PD-MA1 | M9: Konabay | N9: 1 | O9: =IF(ISBLANK(L9),"",IF(OR(ISBLANK(VLOOKUP(L9&"-"&E9,'Np Quality'!A:M,6,FALSE)),ISERROR(VLOOKUP(L9&"-"&E9,'Np Quality'!A:M,6,FALSE))),"-",VLOOKUP(L9&"-"&E9,'Np Quality'!A:M,6,FALSE))) -> NP3 | P9: =IF(ISBLANK(L9),"",IF(OR(ISBLANK(VLOOKUP(L9&"-"&E9,'Np Quality'!A:M,7,FALSE)),ISERROR(VLOOKUP(L9&"-"&E9,'Np Quality'!A:M,7,FALSE))),"-",VLOOKUP(L9&"-"&E9,'Np Quality'!A:M,7,FALSE))) -> - | Q9: =IF(ISBLANK(L9),"",IF(OR(ISBLANK(VLOOKUP(L9&"-"&E9,'Np Quality'!A:M,8,FALSE)),ISERROR(VLOOKUP(L9&"-"&E9,'Np Quality'!A:M,8,FALSE))),"-",VLOOKUP(L9&"-"&E9,'Np Quality'!A:M,8,FALSE))) -> - | R9: =IF(ISBLANK(L9),"",IF(OR(ISBLANK(VLOOKUP(L9&"-"&E9,'Np Quality'!A:M,9,FALSE)),ISERROR(VLOOKUP(L9&"-"&E9,'Np Quality'!A:M,9,FALSE))),"-",VLOOKUP(L9&"-"&E9,'Np Quality'!A:M,9,FALSE))) -> 0.02 | T9: =IF(ISNUMBER(B9),CHOOSE(B9,L9,L9&","&L10,L9&","&L10&","&L11,L9&","&L10&","&L11&","&L12),"") -> PD-MA1 | U9: =IF(ISNUMBER(B9),CHOOSE(B9,M9,M9&","&M10,M9&","&M10&","&M11,M9&","&M10&","&M11&","&M12),"") -> Konabay | W9: 45695 | X9: =MONTH(W9) -> 2 | Y9: =YEAR(W9) -> 2025
A10: =IF(ISBLANK(H10),"",H10&"-"&IF(OR(LEN(I10)=1,LEN(I10)=4),"0"&I10,I10)&"-"&IF(LEN(G10)=1,"0"&G10,G10)) -> D1-01-01 | B10: =IF(AND(A10<>A9,A10<>""),COUNTIF(A:A,A10),"") -> 1 | C10: Vijaya2 | D10: 45684 | E10: =IF(ISBLANK(D10),"",D10-F10) -> 45684 | F10: 0 | G10: 1 | H10: D1 | I10: 1 | J10: Np4 | K10: Pondy1 | L10: PD-MC1 | M10: Konabay | N10: 1 | O10: =IF(ISBLANK(L10),"",IF(OR(ISBLANK(VLOOKUP(L10&"-"&E10,'Np Quality'!A:M,6,FALSE)),ISERROR(VLOOKUP(L10&"-"&E10,'Np Quality'!A:M,6,FALSE))),"-",VLOOKUP(L10&"-"&E10,'Np Quality'!A:M,6,FALSE))) -> NP3 | P10: =IF(ISBLANK(L10),"",IF(OR(ISBLANK(VLOOKUP(L10&"-"&E10,'Np Quality'!A:M,7,FALSE)),ISERROR(VLOOKUP(L10&"-"&E10,'Np Quality'!A:M,7,FALSE))),"-",VLOOKUP(L10&"-"&E10,'Np Quality'!A:M,7,FALSE))) -> - | Q10: =IF(ISBLANK(L10),"",IF(OR(ISBLANK(VLOOKUP(L10&"-"&E10,'Np Quality'!A:M,8,FALSE)),ISERROR(VLOOKUP(L10&"-"&E10,'Np Quality'!A:M,8,FALSE))),"-",VLOOKUP(L10&"-"&E10,'Np Quality'!A:M,8,FALSE))) -> - | R10: =IF(ISBLANK(L10),"",IF(OR(ISBLANK(VLOOKUP(L10&"-"&E10,'Np Quality'!A:M,9,FALSE)),ISERROR(VLOOKUP(L10&"-"&E10,'Np Quality'!A:M,9,FALSE))),"-",VLOOKUP(L10&"-"&E10,'Np Quality'!A:M,9,FALSE))) -> 0.02 | T10: =IF(ISNUMBER(B10),CHOOSE(B10,L10,L10&","&L11,L10&","&L11&","&L12,L10&","&L11&","&L12&","&L13),"") -> PD-MC1 | U10: =IF(ISNUMBER(B10),CHOOSE(B10,M10,M10&","&M11,M10&","&M11&","&M12,M10&","&M11&","&M12&","&M13),"") -> Konabay | W10: 45695 | X10: =MONTH(W10) -> 2 | Y10: =YEAR(W10) -> 2025
A11: =IF(ISBLANK(H11),"",H11&"-"&IF(OR(LEN(I11)=1,LEN(I11)=4),"0"&I11,I11)&"-"&IF(LEN(G11)=1,"0"&G11,G11)) -> D1-02-01 | B11: =IF(AND(A11<>A10,A11<>""),COUNTIF(A:A,A11),"") -> 1 | C11: Vijaya2 | D11: 45684 | E11: =IF(ISBLANK(D11),"",D11-F11) -> 45684 | F11: 0 | G11: 1 | H11: D1 | I11: 2 | J11: Np4 | K11: Vijaya1 | L11: V1-MD1 | M11: Konabay | N11: 1 | O11: =IF(ISBLANK(L11),"",IF(OR(ISBLANK(VLOOKUP(L11&"-"&E11,'Np Quality'!A:M,6,FALSE)),ISERROR(VLOOKUP(L11&"-"&E11,'Np Quality'!A:M,6,FALSE))),"-",VLOOKUP(L11&"-"&E11,'Np Quality'!A:M,6,FALSE))) -> Np4 | P11: =IF(ISBLANK(L11),"",IF(OR(ISBLANK(VLOOKUP(L11&"-"&E11,'Np Quality'!A:M,7,FALSE)),ISERROR(VLOOKUP(L11&"-"&E11,'Np Quality'!A:M,7,FALSE))),"-",VLOOKUP(L11&"-"&E11,'Np Quality'!A:M,7,FALSE))) -> 0.8 | Q11: =IF(ISBLANK(L11),"",IF(OR(ISBLANK(VLOOKUP(L11&"-"&E11,'Np Quality'!A:M,8,FALSE)),ISERROR(VLOOKUP(L11&"-"&E11,'Np Quality'!A:M,8,FALSE))),"-",VLOOKUP(L11&"-"&E11,'Np Quality'!A:M,8,FALSE))) -> 0.8 | R11: =IF(ISBLANK(L11),"",IF(OR(ISBLANK(VLOOKUP(L11&"-"&E11,'Np Quality'!A:M,9,FALSE)),ISERROR(VLOOKUP(L11&"-"&E11,'Np Quality'!A:M,9,FALSE))),"-",VLOOKUP(L11&"-"&E11,'Np Quality'!A:M,9,FALSE))) -> 0.01 | T11: =IF(ISNUMBER(B11),CHOOSE(B11,L11,L11&","&L12,L11&","&L12&","&L13,L11&","&L12&","&L13&","&L14),"") -> V1-MD1 | U11: =IF(ISNUMBER(B11),CHOOSE(B11,M11,M11&","&M12,M11&","&M12&","&M13,M11&","&M12&","&M13&","&M14),"") -> Konabay | W11: 45697 | X11: =MONTH(W11) -> 2 | Y11: =YEAR(W11) -> 2025
A12: =IF(ISBLANK(H12),"",H12&"-"&IF(OR(LEN(I12)=1,LEN(I12)=4),"0"&I12,I12)&"-"&IF(LEN(G12)=1,"0"&G12,G12)) -> D1-03-01 | B12: =IF(AND(A12<>A11,A12<>""),COUNTIF(A:A,A12),"") -> 1 | C12: Vijaya2 | D12: 45685 | E12: =IF(ISBLANK(D12),"",D12-F12) -> 45685 | F12: 0 | G12: 1 | H12: D1 | I12: 3 | J12: Np4 | K12: Vijaya1 | L12: V1-MD1 | M12: Konabay | N12: 1 | O12: =IF(ISBLANK(L12),"",IF(OR(ISBLANK(VLOOKUP(L12&"-"&E12,'Np Quality'!A:M,6,FALSE)),ISERROR(VLOOKUP(L12&"-"&E12,'Np Quality'!A:M,6,FALSE))),"-",VLOOKUP(L12&"-"&E12,'Np Quality'!A:M,6,FALSE))) -> Np4 | P12: =IF(ISBLANK(L12),"",IF(OR(ISBLANK(VLOOKUP(L12&"-"&E12,'Np Quality'!A:M,7,FALSE)),ISERROR(VLOOKUP(L12&"-"&E12,'Np Quality'!A:M,7,FALSE))),"-",VLOOKUP(L12&"-"&E12,'Np Quality'!A:M,7,FALSE))) -> 0.9 | Q12: =IF(ISBLANK(L12),"",IF(OR(ISBLANK(VLOOKUP(L12&"-"&E12,'Np Quality'!A:M,8,FALSE)),ISERROR(VLOOKUP(L12&"-"&E12,'Np Quality'!A:M,8,FALSE))),"-",VLOOKUP(L12&"-"&E12,'Np Quality'!A:M,8,FALSE))) -> 0.9 | R12: =IF(ISBLANK(L12),"",IF(OR(ISBLANK(VLOOKUP(L12&"-"&E12,'Np Quality'!A:M,9,FALSE)),ISERROR(VLOOKUP(L12&"-"&E12,'Np Quality'!A:M,9,FALSE))),"-",VLOOKUP(L12&"-"&E12,'Np Quality'!A:M,9,FALSE))) -> 0 | T12: =IF(ISNUMBER(B12),CHOOSE(B12,L12,L12&","&L13,L12&","&L13&","&L14,L12&","&L13&","&L14&","&L15),"") -> V1-MD1 | U12: =IF(ISNUMBER(B12),CHOOSE(B12,M12,M12&","&M13,M12&","&M13&","&M14,M12&","&M13&","&M14&","&M15),"") -> Konabay | W12: 45697 | X12: =MONTH(W12) -> 2 | Y12: =YEAR(W12) -> 2025
A13: =IF(ISBLANK(H13),"",H13&"-"&IF(OR(LEN(I13)=1,LEN(I13)=4),"0"&I13,I13)&"-"&IF(LEN(G13)=1,"0"&G13,G13)) -> D1-04-01 | B13: =IF(AND(A13<>A12,A13<>""),COUNTIF(A:A,A13),"") -> 1 | C13: Vijaya2 | D13: 45685 | E13: =IF(ISBLANK(D13),"",D13-F13) -> 45685 | F13: 0 | G13: 1 | H13: D1 | I13: 4 | J13: Np4 | K13: Vijaya1 | L13: V1-MD1 | M13: Konabay | N13: 1 | O13: =IF(ISBLANK(L13),"",IF(OR(ISBLANK(VLOOKUP(L13&"-"&E13,'Np Quality'!A:M,6,FALSE)),ISERROR(VLOOKUP(L13&"-"&E13,'Np Quality'!A:M,6,FALSE))),"-",VLOOKUP(L13&"-"&E13,'Np Quality'!A:M,6,FALSE))) -> Np4 | P13: =IF(ISBLANK(L13),"",IF(OR(ISBLANK(VLOOKUP(L13&"-"&E13,'Np Quality'!A:M,7,FALSE)),ISERROR(VLOOKUP(L13&"-"&E13,'Np Quality'!A:M,7,FALSE))),"-",VLOOKUP(L13&"-"&E13,'Np Quality'!A:M,7,FALSE))) -> 0.9 | Q13: =IF(ISBLANK(L13),"",IF(OR(ISBLANK(VLOOKUP(L13&"-"&E13,'Np Quality'!A:M,8,FALSE)),ISERROR(VLOOKUP(L13&"-"&E13,'Np Quality'!A:M,8,FALSE))),"-",VLOOKUP(L13&"-"&E13,'Np Quality'!A:M,8,FALSE))) -> 0.9 | R13: =IF(ISBLANK(L13),"",IF(OR(ISBLANK(VLOOKUP(L13&"-"&E13,'Np Quality'!A:M,9,FALSE)),ISERROR(VLOOKUP(L13&"-"&E13,'Np Quality'!A:M,9,FALSE))),"-",VLOOKUP(L13&"-"&E13,'Np Quality'!A:M,9,FALSE))) -> 0 | T13: =IF(ISNUMBER(B13),CHOOSE(B13,L13,L13&","&L14,L13&","&L14&","&L15,L13&","&L14&","&L15&","&L16),"") -> V1-MD1 | U13: =IF(ISNUMBER(B13),CHOOSE(B13,M13,M13&","&M14,M13&","&M14&","&M15,M13&","&M14&","&M15&","&M16),"") -> Konabay | W13: 45698 | X13: =MONTH(W13) -> 2 | Y13: =YEAR(W13) -> 2025
A14: =IF(ISBLANK(H14),"",H14&"-"&IF(OR(LEN(I14)=1,LEN(I14)=4),"0"&I14,I14)&"-"&IF(LEN(G14)=1,"0"&G14,G14)) -> D1-05-01 | B14: =IF(AND(A14<>A13,A14<>""),COUNTIF(A:A,A14),"") -> 1 | C14: Vijaya2 | D14: 45686 | E14: =IF(ISBLANK(D14),"",D14-F14) -> 45686 | F14: 0 | G14: 1 | H14: D1 | I14: 5 | J14: Np4 | K14: Vijaya1 | L14: V1-MD1 | M14: Konabay | N14: 2 | O14: =IF(ISBLANK(L14),"",IF(OR(ISBLANK(VLOOKUP(L14&"-"&E14,'Np Quality'!A:M,6,FALSE)),ISERROR(VLOOKUP(L14&"-"&E14,'Np Quality'!A:M,6,FALSE))),"-",VLOOKUP(L14&"-"&E14,'Np Quality'!A:M,6,FALSE))) -> Np4 | P14: =IF(ISBLANK(L14),"",IF(OR(ISBLANK(VLOOKUP(L14&"-"&E14,'Np Quality'!A:M,7,FALSE)),ISERROR(VLOOKUP(L14&"-"&E14,'Np Quality'!A:M,7,FALSE))),"-",VLOOKUP(L14&"-"&E14,'Np Quality'!A:M,7,FALSE))) -> 0.9 | Q14: =IF(ISBLANK(L14),"",IF(OR(ISBLANK(VLOOKUP(L14&"-"&E14,'Np Quality'!A:M,8,FALSE)),ISERROR(VLOOKUP(L14&"-"&E14,'Np Quality'!A:M,8,FALSE))),"-",VLOOKUP(L14&"-"&E14,'Np Quality'!A:M,8,FALSE))) -> 0.9 | R14: =IF(ISBLANK(L14),"",IF(OR(ISBLANK(VLOOKUP(L14&"-"&E14,'Np Quality'!A:M,9,FALSE)),ISERROR(VLOOKUP(L14&"-"&E14,'Np Quality'!A:M,9,FALSE))),"-",VLOOKUP(L14&"-"&E14,'Np Quality'!A:M,9,FALSE))) -> 0.01 | T14: =IF(ISNUMBER(B14),CHOOSE(B14,L14,L14&","&L15,L14&","&L15&","&L16,L14&","&L15&","&L16&","&L17),"") -> V1-MD1 | U14: =IF(ISNUMBER(B14),CHOOSE(B14,M14,M14&","&M15,M14&","&M15&","&M16,M14&","&M15&","&M16&","&M17),"") -> Konabay | W14: 45699 | X14: =MONTH(W14) -> 2 | Y14: =YEAR(W14) -> 2025
A15: =IF(ISBLANK(H15),"",H15&"-"&IF(OR(LEN(I15)=1,LEN(I15)=4),"0"&I15,I15)&"-"&IF(LEN(G15)=1,"0"&G15,G15)) -> D1-06-01 | B15: =IF(AND(A15<>A14,A15<>""),COUNTIF(A:A,A15),"") -> 1 | C15: Vijaya2 | D15: 45687 | E15: =IF(ISBLANK(D15),"",D15-F15) -> 45687 | F15: 0 | G15: 1 | H15: D1 | I15: 6 | J15: Np4 | K15: Pondy1 | L15: PD-MA1 | M15: Konabay | N15: 2 | O15: =IF(ISBLANK(L16),"",IF(OR(ISBLANK(VLOOKUP(L16&"-"&E16,'Np Quality'!A:M,6,FALSE)),ISERROR(VLOOKUP(L16&"-"&E16,'Np Quality'!A:M,6,FALSE))),"-",VLOOKUP(L16&"-"&E16,'Np Quality'!A:M,6,FALSE))) -> NP3 | P15: =IF(ISBLANK(L15),"",IF(OR(ISBLANK(VLOOKUP(L15&"-"&E15,'Np Quality'!A:M,7,FALSE)),ISERROR(VLOOKUP(L15&"-"&E15,'Np Quality'!A:M,7,FALSE))),"-",VLOOKUP(L15&"-"&E15,'Np Quality'!A:M,7,FALSE))) -> - | Q15: =IF(ISBLANK(L15),"",IF(OR(ISBLANK(VLOOKUP(L15&"-"&E15,'Np Quality'!A:M,8,FALSE)),ISERROR(VLOOKUP(L15&"-"&E15,'Np Quality'!A:M,8,FALSE))),"-",VLOOKUP(L15&"-"&E15,'Np Quality'!A:M,8,FALSE))) -> - | R15: =IF(ISBLANK(L15),"",IF(OR(ISBLANK(VLOOKUP(L15&"-"&E15,'Np Quality'!A:M,9,FALSE)),ISERROR(VLOOKUP(L15&"-"&E15,'Np Quality'!A:M,9,FALSE))),"-",VLOOKUP(L15&"-"&E15,'Np Quality'!A:M,9,FALSE))) -> 0.02 | T15: =IF(ISNUMBER(B15),CHOOSE(B15,L15,L15&","&L16,L15&","&L16&","&L17,L15&","&L16&","&L17&","&L18),"") -> PD-MA1 | U15: =IF(ISNUMBER(B15),CHOOSE(B15,M15,M15&","&M16,M15&","&M16&","&M17,M15&","&M16&","&M17&","&M18),"") -> Konabay | W15: 45699 | X15: =MONTH(W15) -> 2 | Y15: =YEAR(W15) -> 2025
A16: =IF(ISBLANK(H16),"",H16&"-"&IF(OR(LEN(I16)=1,LEN(I16)=4),"0"&I16,I16)&"-"&IF(LEN(G16)=1,"0"&G16,G16)) -> D1-07-01 | B16: =IF(AND(A16<>A15,A16<>""),COUNTIF(A:A,A16),"") -> 1 | C16: Vijaya2 | D16: 45687 | E16: =IF(ISBLANK(D16),"",D16-F16) -> 45687 | F16: 0 | G16: 1 | H16: D1 | I16: 7 | J16: Np4 | K16: Pondy1 | L16: PD-MA1 | M16: Konabay | N16: 2 | O16: =IF(ISBLANK(L16),"",IF(OR(ISBLANK(VLOOKUP(L16&"-"&E16,'Np Quality'!A:M,6,FALSE)),ISERROR(VLOOKUP(L16&"-"&E16,'Np Quality'!A:M,6,FALSE))),"-",VLOOKUP(L16&"-"&E16,'Np Quality'!A:M,6,FALSE))) -> NP3 | P16: =IF(ISBLANK(L17),"",IF(OR(ISBLANK(VLOOKUP(L17&"-"&E17,'Np Quality'!A:M,7,FALSE)),ISERROR(VLOOKUP(L17&"-"&E17,'Np Quality'!A:M,7,FALSE))),"-",VLOOKUP(L17&"-"&E17,'Np Quality'!A:M,7,FALSE))) -> - | Q16: =IF(ISBLANK(L16),"",IF(OR(ISBLANK(VLOOKUP(L16&"-"&E16,'Np Quality'!A:M,8,FALSE)),ISERROR(VLOOKUP(L16&"-"&E16,'Np Quality'!A:M,8,FALSE))),"-",VLOOKUP(L16&"-"&E16,'Np Quality'!A:M,8,FALSE))) -> - | R16: =IF(ISBLANK(L16),"",IF(OR(ISBLANK(VLOOKUP(L16&"-"&E16,'Np Quality'!A:M,9,FALSE)),ISERROR(VLOOKUP(L16&"-"&E16,'Np Quality'!A:M,9,FALSE))),"-",VLOOKUP(L16&"-"&E16,'Np Quality'!A:M,9,FALSE))) -> 0.02 | T16: =IF(ISNUMBER(B16),CHOOSE(B16,L16,L16&","&L17,L16&","&L17&","&L18,L16&","&L17&","&L18&","&L19),"") -> PD-MA1 | U16: =IF(ISNUMBER(B16),CHOOSE(B16,M16,M16&","&M17,M16&","&M17&","&M18,M16&","&M17&","&M18&","&M19),"") -> Konabay | W16: 45699 | X16: =MONTH(W16) -> 2 | Y16: =YEAR(W16) -> 2025
A17: =IF(ISBLANK(H17),"",H17&"-"&IF(OR(LEN(I17)=1,LEN(I17)=4),"0"&I17,I17)&"-"&IF(LEN(G17)=1,"0"&G17,G17)) -> D1-08-01 | B17: =IF(AND(A17<>A16,A17<>""),COUNTIF(A:A,A17),"") -> 1 | C17: Vijaya2 | D17: 45687 | E17: =IF(ISBLANK(D17),"",D17-F17) -> 45687 | F17: 0 | G17: 1 | H17: D1 | I17: 8 | J17: Np4 | K17: Pondy1 | L17: PD-MC1 | M17: Konabay | N17: 1 | O17: =IF(ISBLANK(L17),"",IF(OR(ISBLANK(VLOOKUP(L17&"-"&E17,'Np Quality'!A:M,6,FALSE)),ISERROR(VLOOKUP(L17&"-"&E17,'Np Quality'!A:M,6,FALSE))),"-",VLOOKUP(L17&"-"&E17,'Np Quality'!A:M,6,FALSE))) -> NP3 | P17: =IF(ISBLANK(L17),"",IF(OR(ISBLANK(VLOOKUP(L17&"-"&E17,'Np Quality'!A:M,7,FALSE)),ISERROR(VLOOKUP(L17&"-"&E17,'Np Quality'!A:M,7,FALSE))),"-",VLOOKUP(L17&"-"&E17,'Np Quality'!A:M,7,FALSE))) -> - | Q17: =IF(ISBLANK(L18),"",IF(OR(ISBLANK(VLOOKUP(L18&"-"&E18,'Np Quality'!A:M,8,FALSE)),ISERROR(VLOOKUP(L18&"-"&E18,'Np Quality'!A:M,8,FALSE))),"-",VLOOKUP(L18&"-"&E18,'Np Quality'!A:M,8,FALSE))) -> 0.8 | R17: =IF(ISBLANK(L17),"",IF(OR(ISBLANK(VLOOKUP(L17&"-"&E17,'Np Quality'!A:M,9,FALSE)),ISERROR(VLOOKUP(L17&"-"&E17,'Np Quality'!A:M,9,FALSE))),"-",VLOOKUP(L17&"-"&E17,'Np Quality'!A:M,9,FALSE))) -> 0.01 | T17: =IF(ISNUMBER(B17),CHOOSE(B17,L17,L17&","&L18,L17&","&L18&","&L19,L17&","&L18&","&L19&","&L20),"") -> PD-MC1 | U17: =IF(ISNUMBER(B17),CHOOSE(B17,M17,M17&","&M18,M17&","&M18&","&M19,M17&","&M18&","&M19&","&M20),"") -> Konabay | W17: 45700 | X17: =MONTH(W17) -> 2 | Y17: =YEAR(W17) -> 2025
A18: =IF(ISBLANK(H18),"",H18&"-"&IF(OR(LEN(I18)=1,LEN(I18)=4),"0"&I18,I18)&"-"&IF(LEN(G18)=1,"0"&G18,G18)) -> D1-09-01 | B18: =IF(AND(A18<>A17,A18<>""),COUNTIF(A:A,A18),"") -> 1 | C18: Vijaya2 | D18: 45687 | E18: =IF(ISBLANK(D18),"",D18-F18) -> 45687 | F18: 0 | G18: 1 | H18: D1 | I18: 9 | J18: Np4 | K18: Vijaya1 | L18: V1-MD1 | M18: Konabay | N18: 2 | O18: =IF(ISBLANK(L18),"",IF(OR(ISBLANK(VLOOKUP(L18&"-"&E18,'Np Quality'!A:M,6,FALSE)),ISERROR(VLOOKUP(L18&"-"&E18,'Np Quality'!A:M,6,FALSE))),"-",VLOOKUP(L18&"-"&E18,'Np Quality'!A:M,6,FALSE))) -> Np4 | P18: =IF(ISBLANK(L18),"",IF(OR(ISBLANK(VLOOKUP(L18&"-"&E18,'Np Quality'!A:M,7,FALSE)),ISERROR(VLOOKUP(L18&"-"&E18,'Np Quality'!A:M,7,FALSE))),"-",VLOOKUP(L18&"-"&E18,'Np Quality'!A:M,7,FALSE))) -> 0.8 | Q18: =IF(ISBLANK(L18),"",IF(OR(ISBLANK(VLOOKUP(L18&"-"&E18,'Np Quality'!A:M,8,FALSE)),ISERROR(VLOOKUP(L18&"-"&E18,'Np Quality'!A:M,8,FALSE))),"-",VLOOKUP(L18&"-"&E18,'Np Quality'!A:M,8,FALSE))) -> 0.8 | R18: =IF(ISBLANK(L19),"",IF(OR(ISBLANK(VLOOKUP(L19&"-"&E19,'Np Quality'!A:M,9,FALSE)),ISERROR(VLOOKUP(L19&"-"&E19,'Np Quality'!A:M,9,FALSE))),"-",VLOOKUP(L19&"-"&E19,'Np Quality'!A:M,9,FALSE))) -> 0 | T18: =IF(ISNUMBER(B18),CHOOSE(B18,L18,L18&","&L19,L18&","&L19&","&L20,L18&","&L19&","&L20&","&L21),"") -> V1-MD1 | U18: =IF(ISNUMBER(B18),CHOOSE(B18,M18,M18&","&M19,M18&","&M19&","&M20,M18&","&M19&","&M20&","&M21),"") -> Konabay | W18: 45700 | X18: =MONTH(W18) -> 2 | Y18: =YEAR(W18) -> 2025
A19: =IF(ISBLANK(H19),"",H19&"-"&IF(OR(LEN(I19)=1,LEN(I19)=4),"0"&I19,I19)&"-"&IF(LEN(G19)=1,"0"&G19,G19)) -> D1-10-01 | B19: =IF(AND(A19<>A18,A19<>""),COUNTIF(A:A,A19),"") -> 1 | C19: Vijaya2 | D19: 45688 | E19: =IF(ISBLANK(D19),"",D19-F19) -> 45688 | F19: 0 | G19: 1 | H19: D1 | I19: 10 | J19: Np4 | K19: Vijaya1 | L19: V1-MD1 | M19: Konabay | N19: 2 | O19: =IF(ISBLANK(L19),"",IF(OR(ISBLANK(VLOOKUP(L19&"-"&E19,'Np Quality'!A:M,6,FALSE)),ISERROR(VLOOKUP(L19&"-"&E19,'Np Quality'!A:M,6,FALSE))),"-",VLOOKUP(L19&"-"&E19,'Np Quality'!A:M,6,FALSE))) -> Np4 | P19: =IF(ISBLANK(L19),"",IF(OR(ISBLANK(VLOOKUP(L19&"-"&E19,'Np Quality'!A:M,7,FALSE)),ISERROR(VLOOKUP(L19&"-"&E19,'Np Quality'!A:M,7,FALSE))),"-",VLOOKUP(L19&"-"&E19,'Np Quality'!A:M,7,FALSE))) -> 0.9 | Q19: =IF(ISBLANK(L19),"",IF(OR(ISBLANK(VLOOKUP(L19&"-"&E19,'Np Quality'!A:M,8,FALSE)),ISERROR(VLOOKUP(L19&"-"&E19,'Np Quality'!A:M,8,FALSE))),"-",VLOOKUP(L19&"-"&E19,'Np Quality'!A:M,8,FALSE))) -> 0.9 | R19: =IF(ISBLANK(L19),"",IF(OR(ISBLANK(VLOOKUP(L19&"-"&E19,'Np Quality'!A:M,9,FALSE)),ISERROR(VLOOKUP(L19&"-"&E19,'Np Quality'!A:M,9,FALSE))),"-",VLOOKUP(L19&"-"&E19,'Np Quality'!A:M,9,FALSE))) -> 0 | T19: =IF(ISNUMBER(B19),CHOOSE(B19,L19,L19&","&L20,L19&","&L20&","&L21,L19&","&L20&","&L21&","&L22),"") -> V1-MD1 | U19: =IF(ISNUMBER(B19),CHOOSE(B19,M19,M19&","&M20,M19&","&M20&","&M21,M19&","&M20&","&M21&","&M22),"") -> Konabay | W19: 45700 | X19: =MONTH(W19) -> 2 | Y19: =YEAR(W19) -> 2025
A20: =IF(ISBLANK(H20),"",H20&"-"&IF(OR(LEN(I20)=1,LEN(I20)=4),"0"&I20,I20)&"-"&IF(LEN(G20)=1,"0"&G20,G20)) -> A1-01-01 | B20: =IF(AND(A20<>A19,A20<>""),COUNTIF(A:A,A20),"") -> 1 | C20: Vijaya2 | D20: 45694 | E20: =IF(ISBLANK(D20),"",D20-F20) -> 45694 | F20: 0 | G20: 1 | H20: A1 | I20: 1 | J20: Np4 | K20: Vijaya1 | L20: V1-MB1 | M20: SIS | N20: 2.5 | O20: =IF(ISBLANK(L20),"",IF(OR(ISBLANK(VLOOKUP(L20&"-"&E20,'Np Quality'!A:M,6,FALSE)),ISERROR(VLOOKUP(L20&"-"&E20,'Np Quality'!A:M,6,FALSE))),"-",VLOOKUP(L20&"-"&E20,'Np Quality'!A:M,6,FALSE))) -> Np4 | P20: =IF(ISBLANK(L20),"",IF(OR(ISBLANK(VLOOKUP(L20&"-"&E20,'Np Quality'!A:M,7,FALSE)),ISERROR(VLOOKUP(L20&"-"&E20,'Np Quality'!A:M,7,FALSE))),"-",VLOOKUP(L20&"-"&E20,'Np Quality'!A:M,7,FALSE))) -> 0.9 | Q20: =IF(ISBLANK(L20),"",IF(OR(ISBLANK(VLOOKUP(L20&"-"&E20,'Np Quality'!A:M,8,FALSE)),ISERROR(VLOOKUP(L20&"-"&E20,'Np Quality'!A:M,8,FALSE))),"-",VLOOKUP(L20&"-"&E20,'Np Quality'!A:M,8,FALSE))) -> 0.9 | R20: =IF(ISBLANK(L20),"",IF(OR(ISBLANK(VLOOKUP(L20&"-"&E20,'Np Quality'!A:M,9,FALSE)),ISERROR(VLOOKUP(L20&"-"&E20,'Np Quality'!A:M,9,FALSE))),"-",VLOOKUP(L20&"-"&E20,'Np Quality'!A:M,9,FALSE))) -> 0 | T20: =IF(ISNUMBER(B20),CHOOSE(B20,L20,L20&","&L21,L20&","&L21&","&L22,L20&","&L21&","&L22&","&L23),"") -> V1-MB1 | U20: =IF(ISNUMBER(B20),CHOOSE(B20,M20,M20&","&M21,M20&","&M21&","&M22,M20&","&M21&","&M22&","&M23),"") -> SIS | W20: 45706 | X20: =MONTH(W20) -> 2 | Y20: =YEAR(W20) -> 2025
A21: =IF(ISBLANK(H21),"",H21&"-"&IF(OR(LEN(I21)=1,LEN(I21)=4),"0"&I21,I21)&"-"&IF(LEN(G21)=1,"0"&G21,G21)) -> A1-02-01 | B21: =IF(AND(A21<>A20,A21<>""),COUNTIF(A:A,A21),"") -> 1 | C21: Vijaya2 | D21: 45694 | E21: =IF(ISBLANK(D21),"",D21-F21) -> 45694 | F21: 0 | G21: 1 | H21: A1 | I21: 2 | J21: Np4 | K21: Vijaya1 | L21: V1-MD1 | M21: Konabay | N21: 1 | O21: =IF(ISBLANK(L21),"",IF(OR(ISBLANK(VLOOKUP(L21&"-"&E21,'Np Quality'!A:M,6,FALSE)),ISERROR(VLOOKUP(L21&"-"&E21,'Np Quality'!A:M,6,FALSE))),"-",VLOOKUP(L21&"-"&E21,'Np Quality'!A:M,6,FALSE))) -> Np4 | P21: =IF(ISBLANK(L21),"",IF(OR(ISBLANK(VLOOKUP(L21&"-"&E21,'Np Quality'!A:M,7,FALSE)),ISERROR(VLOOKUP(L21&"-"&E21,'Np Quality'!A:M,7,FALSE))),"-",VLOOKUP(L21&"-"&E21,'Np Quality'!A:M,7,FALSE))) -> 0.9 | Q21: =IF(ISBLANK(L21),"",IF(OR(ISBLANK(VLOOKUP(L21&"-"&E21,'Np Quality'!A:M,8,FALSE)),ISERROR(VLOOKUP(L21&"-"&E21,'Np Quality'!A:M,8,FALSE))),"-",VLOOKUP(L21&"-"&E21,'Np Quality'!A:M,8,FALSE))) -> 0.9 | R21: =IF(ISBLANK(L21),"",IF(OR(ISBLANK(VLOOKUP(L21&"-"&E21,'Np Quality'!A:M,9,FALSE)),ISERROR(VLOOKUP(L21&"-"&E21,'Np Quality'!A:M,9,FALSE))),"-",VLOOKUP(L21&"-"&E21,'Np Quality'!A:M,9,FALSE))) -> 0 | T21: =IF(ISNUMBER(B21),CHOOSE(B21,L21,L21&","&L22,L21&","&L22&","&L23,L21&","&L22&","&L23&","&L24),"") -> V1-MD1 | U21: =IF(ISNUMBER(B21),CHOOSE(B21,M21,M21&","&M22,M21&","&M22&","&M23,M21&","&M22&","&M23&","&M24),"") -> Konabay | W21: 45706 | X21: =MONTH(W21) -> 2 | Y21: =YEAR(W21) -> 2025
A22: =IF(ISBLANK(H22),"",H22&"-"&IF(OR(LEN(I22)=1,LEN(I22)=4),"0"&I22,I22)&"-"&IF(LEN(G22)=1,"0"&G22,G22)) -> A1-03-01 | B22: =IF(AND(A22<>A21,A22<>""),COUNTIF(A:A,A22),"") -> 1 | C22: Vijaya2 | D22: 45694 | E22: =IF(ISBLANK(D22),"",D22-F22) -> 45694 | F22: 0 | G22: 1 | H22: A1 | I22: 3 | J22: Np4 | K22: Vijaya1 | L22: V1-MD1 | M22: Konabay | N22: 1 | O22: =IF(ISBLANK(L22),"",IF(OR(ISBLANK(VLOOKUP(L22&"-"&E22,'Np Quality'!A:M,6,FALSE)),ISERROR(VLOOKUP(L22&"-"&E22,'Np Quality'!A:M,6,FALSE))),"-",VLOOKUP(L22&"-"&E22,'Np Quality'!A:M,6,FALSE))) -> Np4 | P22: =IF(ISBLANK(L22),"",IF(OR(ISBLANK(VLOOKUP(L22&"-"&E22,'Np Quality'!A:M,7,FALSE)),ISERROR(VLOOKUP(L22&"-"&E22,'Np Quality'!A:M,7,FALSE))),"-",VLOOKUP(L22&"-"&E22,'Np Quality'!A:M,7,FALSE))) -> 0.9 | Q22: =IF(ISBLANK(L22),"",IF(OR(ISBLANK(VLOOKUP(L22&"-"&E22,'Np Quality'!A:M,8,FALSE)),ISERROR(VLOOKUP(L22&"-"&E22,'Np Quality'!A:M,8,FALSE))),"-",VLOOKUP(L22&"-"&E22,'Np Quality'!A:M,8,FALSE))) -> 0.9 | R22: =IF(ISBLANK(L22),"",IF(OR(ISBLANK(VLOOKUP(L22&"-"&E22,'Np Quality'!A:M,9,FALSE)),ISERROR(VLOOKUP(L22&"-"&E22,'Np Quality'!A:M,9,FALSE))),"-",VLOOKUP(L22&"-"&E22,'Np Quality'!A:M,9,FALSE))) -> 0 | T22: =IF(ISNUMBER(B22),CHOOSE(B22,L22,L22&","&L23,L22&","&L23&","&L24,L22&","&L23&","&L24&","&L25),"") -> V1-MD1 | U22: =IF(ISNUMBER(B22),CHOOSE(B22,M22,M22&","&M23,M22&","&M23&","&M24,M22&","&M23&","&M24&","&M25),"") -> Konabay | W22: 45707 | X22: =MONTH(W22) -> 2 | Y22: =YEAR(W22) -> 2025
A23: =IF(ISBLANK(H23),"",H23&"-"&IF(OR(LEN(I23)=1,LEN(I23)=4),"0"&I23,I23)&"-"&IF(LEN(G23)=1,"0"&G23,G23)) -> A1-04-01 | B23: =IF(AND(A23<>A22,A23<>""),COUNTIF(A:A,A23),"") -> 1 | C23: Vijaya2 | D23: 45695 | E23: =IF(ISBLANK(D23),"",D23-F23) -> 45695 | F23: 0 | G23: 1 | H23: A1 | I23: 4 | J23: Np4 | K23: Pondy1 | L23: PD-MA1 | M23: Konabay | N23: 1.67 | O23: =IF(ISBLANK(L23),"",IF(OR(ISBLANK(VLOOKUP(L23&"-"&E23,'Np Quality'!A:M,6,FALSE)),ISERROR(VLOOKUP(L23&"-"&E23,'Np Quality'!A:M,6,FALSE))),"-",VLOOKUP(L23&"-"&E23,'Np Quality'!A:M,6,FALSE))) -> NP3 | P23: =IF(ISBLANK(L23),"",IF(OR(ISBLANK(VLOOKUP(L23&"-"&E23,'Np Quality'!A:M,7,FALSE)),ISERROR(VLOOKUP(L23&"-"&E23,'Np Quality'!A:M,7,FALSE))),"-",VLOOKUP(L23&"-"&E23,'Np Quality'!A:M,7,FALSE))) -> - | Q23: =IF(ISBLANK(L23),"",IF(OR(ISBLANK(VLOOKUP(L23&"-"&E23,'Np Quality'!A:M,8,FALSE)),ISERROR(VLOOKUP(L23&"-"&E23,'Np Quality'!A:M,8,FALSE))),"-",VLOOKUP(L23&"-"&E23,'Np Quality'!A:M,8,FALSE))) -> - | R23: =IF(ISBLANK(L23),"",IF(OR(ISBLANK(VLOOKUP(L23&"-"&E23,'Np Quality'!A:M,9,FALSE)),ISERROR(VLOOKUP(L23&"-"&E23,'Np Quality'!A:M,9,FALSE))),"-",VLOOKUP(L23&"-"&E23,'Np Quality'!A:M,9,FALSE))) -> 0.01 | T23: =IF(ISNUMBER(B23),CHOOSE(B23,L23,L23&","&L24,L23&","&L24&","&L25,L23&","&L24&","&L25&","&L26),"") -> PD-MA1 | U23: =IF(ISNUMBER(B23),CHOOSE(B23,M23,M23&","&M24,M23&","&M24&","&M25,M23&","&M24&","&M25&","&M26),"") -> Konabay | W23: 45708 | X23: =MONTH(W23) -> 2 | Y23: =YEAR(W23) -> 2025
A24: =IF(ISBLANK(H24),"",H24&"-"&IF(OR(LEN(I24)=1,LEN(I24)=4),"0"&I24,I24)&"-"&IF(LEN(G24)=1,"0"&G24,G24)) -> A1-05-01 | B24: =IF(AND(A24<>A23,A24<>""),COUNTIF(A:A,A24),"") -> 1 | C24: Vijaya2 | D24: 45695 | E24: =IF(ISBLANK(D24),"",D24-F24) -> 45695 | F24: 0 | G24: 1 | H24: A1 | I24: 5 | J24: Np4 | K24: Pondy1 | L24: PD-MA1 | M24: Konabay | N24: 1.67 | O24: =IF(ISBLANK(L24),"",IF(OR(ISBLANK(VLOOKUP(L24&"-"&E24,'Np Quality'!A:M,6,FALSE)),ISERROR(VLOOKUP(L24&"-"&E24,'Np Quality'!A:M,6,FALSE))),"-",VLOOKUP(L24&"-"&E24,'Np Quality'!A:M,6,FALSE))) -> NP3 | P24: =IF(ISBLANK(L24),"",IF(OR(ISBLANK(VLOOKUP(L24&"-"&E24,'Np Quality'!A:M,7,FALSE)),ISERROR(VLOOKUP(L24&"-"&E24,'Np Quality'!A:M,7,FALSE))),"-",VLOOKUP(L24&"-"&E24,'Np Quality'!A:M,7,FALSE))) -> - | Q24: =IF(ISBLANK(L24),"",IF(OR(ISBLANK(VLOOKUP(L24&"-"&E24,'Np Quality'!A:M,8,FALSE)),ISERROR(VLOOKUP(L24&"-"&E24,'Np Quality'!A:M,8,FALSE))),"-",VLOOKUP(L24&"-"&E24,'Np Quality'!A:M,8,FALSE))) -> - | R24: =IF(ISBLANK(L24),"",IF(OR(ISBLANK(VLOOKUP(L24&"-"&E24,'Np Quality'!A:M,9,FALSE)),ISERROR(VLOOKUP(L24&"-"&E24,'Np Quality'!A:M,9,FALSE))),"-",VLOOKUP(L24&"-"&E24,'Np Quality'!A:M,9,FALSE))) -> 0.01 | T24: =IF(ISNUMBER(B24),CHOOSE(B24,L24,L24&","&L25,L24&","&L25&","&L26,L24&","&L25&","&L26&","&L27),"") -> PD-MA1 | U24: =IF(ISNUMBER(B24),CHOOSE(B24,M24,M24&","&M25,M24&","&M25&","&M26,M24&","&M25&","&M26&","&M27),"") -> Konabay | W24: 45708 | X24: =MONTH(W24) -> 2 | Y24: =YEAR(W24) -> 2025
A25: =IF(ISBLANK(H25),"",H25&"-"&IF(OR(LEN(I25)=1,LEN(I25)=4),"0"&I25,I25)&"-"&IF(LEN(G25)=1,"0"&G25,G25)) -> A1-06-01 | B25: =IF(AND(A25<>A24,A25<>""),COUNTIF(A:A,A25),"") -> 1 | C25: Vijaya2 | D25: 45695 | E25: =IF(ISBLANK(D25),"",D25-F25) -> 45695 | F25: 0 | G25: 1 | H25: A1 | I25: 6 | J25: Np4 | K25: Pondy1 | L25: PD-MA1 | M25: Konabay | N25: 1.66 | O25: =IF(ISBLANK(L26),"",IF(OR(ISBLANK(VLOOKUP(L26&"-"&E26,'Np Quality'!A:M,6,FALSE)),ISERROR(VLOOKUP(L26&"-"&E26,'Np Quality'!A:M,6,FALSE))),"-",VLOOKUP(L26&"-"&E26,'Np Quality'!A:M,6,FALSE))) -> Np4 | P25: =IF(ISBLANK(L25),"",IF(OR(ISBLANK(VLOOKUP(L25&"-"&E25,'Np Quality'!A:M,7,FALSE)),ISERROR(VLOOKUP(L25&"-"&E25,'Np Quality'!A:M,7,FALSE))),"-",VLOOKUP(L25&"-"&E25,'Np Quality'!A:M,7,FALSE))) -> - | Q25: =IF(ISBLANK(L25),"",IF(OR(ISBLANK(VLOOKUP(L25&"-"&E25,'Np Quality'!A:M,8,FALSE)),ISERROR(VLOOKUP(L25&"-"&E25,'Np Quality'!A:M,8,FALSE))),"-",VLOOKUP(L25&"-"&E25,'Np Quality'!A:M,8,FALSE))) -> - | R25: =IF(ISBLANK(L25),"",IF(OR(ISBLANK(VLOOKUP(L25&"-"&E25,'Np Quality'!A:M,9,FALSE)),ISERROR(VLOOKUP(L25&"-"&E25,'Np Quality'!A:M,9,FALSE))),"-",VLOOKUP(L25&"-"&E25,'Np Quality'!A:M,9,FALSE))) -> 0.01 | T25: =IF(ISNUMBER(B25),CHOOSE(B25,L25,L25&","&L26,L25&","&L26&","&L27,L25&","&L26&","&L27&","&L28),"") -> PD-MA1 | U25: =IF(ISNUMBER(B25),CHOOSE(B25,M25,M25&","&M26,M25&","&M26&","&M27,M25&","&M26&","&M27&","&M28),"") -> Konabay | W25: 45709 | X25: =MONTH(W25) -> 2 | Y25: =YEAR(W25) -> 2025
A26: =IF(ISBLANK(H26),"",H26&"-"&IF(OR(LEN(I26)=1,LEN(I26)=4),"0"&I26,I26)&"-"&IF(LEN(G26)=1,"0"&G26,G26)) -> A1-07-01 | B26: =IF(AND(A26<>A25,A26<>""),COUNTIF(A:A,A26),"") -> 1 | C26: Vijaya2 | D26: 45695 | E26: =IF(ISBLANK(D26),"",D26-F26) -> 45695 | F26: 0 | G26: 1 | H26: A1 | I26: 7 | J26: Np4 | K26: Vijaya1 | L26: V1-MB1 | M26: SIS | N26: 1.25 | O26: =IF(ISBLANK(L26),"",IF(OR(ISBLANK(VLOOKUP(L26&"-"&E26,'Np Quality'!A:M,6,FALSE)),ISERROR(VLOOKUP(L26&"-"&E26,'Np Quality'!A:M,6,FALSE))),"-",VLOOKUP(L26&"-"&E26,'Np Quality'!A:M,6,FALSE))) -> Np4 | P26: =IF(ISBLANK(L27),"",IF(OR(ISBLANK(VLOOKUP(L27&"-"&E27,'Np Quality'!A:M,7,FALSE)),ISERROR(VLOOKUP(L27&"-"&E27,'Np Quality'!A:M,7,FALSE))),"-",VLOOKUP(L27&"-"&E27,'Np Quality'!A:M,7,FALSE))) -> 0.9 | Q26: =IF(ISBLANK(L26),"",IF(OR(ISBLANK(VLOOKUP(L26&"-"&E26,'Np Quality'!A:M,8,FALSE)),ISERROR(VLOOKUP(L26&"-"&E26,'Np Quality'!A:M,8,FALSE))),"-",VLOOKUP(L26&"-"&E26,'Np Quality'!A:M,8,FALSE))) -> 0.9 | R26: =IF(ISBLANK(L26),"",IF(OR(ISBLANK(VLOOKUP(L26&"-"&E26,'Np Quality'!A:M,9,FALSE)),ISERROR(VLOOKUP(L26&"-"&E26,'Np Quality'!A:M,9,FALSE))),"-",VLOOKUP(L26&"-"&E26,'Np Quality'!A:M,9,FALSE))) -> 0 | T26: =IF(ISNUMBER(B26),CHOOSE(B26,L26,L26&","&L27,L26&","&L27&","&L28,L26&","&L27&","&L28&","&L29),"") -> V1-MB1 | U26: =IF(ISNUMBER(B26),CHOOSE(B26,M26,M26&","&M27,M26&","&M27&","&M28,M26&","&M27&","&M28&","&M29),"") -> SIS | W26: 45708 | X26: =MONTH(W26) -> 2 | Y26: =YEAR(W26) -> 2025
A27: =IF(ISBLANK(H27),"",H27&"-"&IF(OR(LEN(I27)=1,LEN(I27)=4),"0"&I27,I27)&"-"&IF(LEN(G27)=1,"0"&G27,G27)) -> A1-08-01 | B27: =IF(AND(A27<>A26,A27<>""),COUNTIF(A:A,A27),"") -> 1 | C27: Vijaya2 | D27: 45695 | E27: =IF(ISBLANK(D27),"",D27-F27) -> 45695 | F27: 0 | G27: 1 | H27: A1 | I27: 8 | J27: Np4 | K27: Vijaya1 | L27: V1-MB1 | M27: SIS | N27: 1.25 | O27: =IF(ISBLANK(L27),"",IF(OR(ISBLANK(VLOOKUP(L27&"-"&E27,'Np Quality'!A:M,6,FALSE)),ISERROR(VLOOKUP(L27&"-"&E27,'Np Quality'!A:M,6,FALSE))),"-",VLOOKUP(L27&"-"&E27,'Np Quality'!A:M,6,FALSE))) -> Np4 | P27: =IF(ISBLANK(L27),"",IF(OR(ISBLANK(VLOOKUP(L27&"-"&E27,'Np Quality'!A:M,7,FALSE)),ISERROR(VLOOKUP(L27&"-"&E27,'Np Quality'!A:M,7,FALSE))),"-",VLOOKUP(L27&"-"&E27,'Np Quality'!A:M,7,FALSE))) -> 0.9 | Q27: =IF(ISBLANK(L28),"",IF(OR(ISBLANK(VLOOKUP(L28&"-"&E28,'Np Quality'!A:M,8,FALSE)),ISERROR(VLOOKUP(L28&"-"&E28,'Np Quality'!A:M,8,FALSE))),"-",VLOOKUP(L28&"-"&E28,'Np Quality'!A:M,8,FALSE))) -> 0.9 | R27: =IF(ISBLANK(L27),"",IF(OR(ISBLANK(VLOOKUP(L27&"-"&E27,'Np Quality'!A:M,9,FALSE)),ISERROR(VLOOKUP(L27&"-"&E27,'Np Quality'!A:M,9,FALSE))),"-",VLOOKUP(L27&"-"&E27,'Np Quality'!A:M,9,FALSE))) -> 0 | T27: =IF(ISNUMBER(B27),CHOOSE(B27,L27,L27&","&L28,L27&","&L28&","&L29,L27&","&L28&","&L29&","&L30),"") -> V1-MB1 | U27: =IF(ISNUMBER(B27),CHOOSE(B27,M27,M27&","&M28,M27&","&M28&","&M29,M27&","&M28&","&M29&","&M30),"") -> SIS | W27: 45708 | X27: =MONTH(W27) -> 2 | Y27: =YEAR(W27) -> 2025
